Workbook
Name CPDK: DVDK!$C$4:$D$399
Name ECVAN: Data!$B$29:$B$30
Name HERIO: Data!$B$5
Name LAC.HONG: Data!$B$27:$B$28
Name LIMO: Data!$B$13
Name MANHOM: Data!$J$2:$J$13
Name MANHOM1: Data!$J$2:$J$13
Name MANHOMDOIXE: Data!$AH$14:$AH$15
Name MANHOMKV: Data!$AH$2:$AH$8
Name MINIO: Data!$B$2
Name NAM: Data!#REF!
Name NERIO: Data!$B$8
Name TAY: Data!#REF!
Name TONGHOP: '[1]1.DT'!$A$2:$CA$202
Name TRUNG: Data!#REF!
Name VF.3: Data!$B$3:$B$4
Name VF.5: Data!$B$6:$B$7
Name VF.6: Data!$B$9:$B$12
Name VF.7: Data!$B$14:$B$18
Name VF.8: Data!$B$19:$B$21
Name VF.9: Data!$B$22:$B$26

Sheet All Info
A1: GIÁ XE | B1: LÃI SUẤT | C1: SỐ TIỀN HẰNG THÁNG
C2: 0.1 | F2: 0.15 | I2: 0.2
C3: 7Y | D3: 6Y | E3: 5Y | F3: 7Y | G3: 6Y | H3: 5Y | I3: 7Y | J3: 6Y | K3: 5Y
C4: TPBank
A5: 1155000000 | B5: 0.12 | C5: =#REF!+#REF! -> #REF! | D5: =#REF!+#REF! -> #REF! | E5: =#REF!+#REF! -> #REF! | F5: =#REF!+#REF! -> #REF! | G5: =#REF!+#REF! -> #REF! | H5: =#REF!+#REF! -> #REF! | I5: =#REF! -> #REF! | J5: =#REF! -> #REF! | K5: =#REF! -> #REF!
C6: 15% | G6: 20%
C7: 4Y | D7: 5Y | E7: 6Y | F7: 7Y | G7: 4Y | H7: 5Y | I7: 6Y | J7: 7Y | K7: 8Y
C8: Other Bank
B9: 0.12 | C9: =#REF! -> #REF! | D9: =#REF! -> #REF! | E9: =#REF! -> #REF! | F9: =#REF! -> #REF! | G9: =#REF! -> #REF! | H9: =#REF! -> #REF! | I9: =#REF! -> #REF! | J9: =#REF! -> #REF! | K9: =#REF! -> #REF!

Sheet BG New
A2: =VLOOKUP(L13,Data!A35:B45,2,0) -> #VALUE! | E2: THÔNG SỐ CƠ BẢN | F2: #VALUE! | G2: =UPPER(Z25) -> QUÃNG ĐƯỜNG DI CHUYỂN DỰ KIẾN 496KM | K2: Khung thuế HCM | L2: =V16 -> 0 | N2: TRA CỨU ĐỊA CHỈ ĐĂNG KÝ XE | Q2: KHÔNG XE | R2: CP ỨNG | S2: LƯU Ý THUẾ ĐĂNG KÝ XE
K3: Lệch | L3: =G26-L2 -> 0 | Q3: Không xe | R3: 1500000
F4: #VALUE! | G4: =UPPER(Z20) -> THỜI GIAN NẠP PIN (10 - 70%) < 28 PHÚT | K4: Disble ! | Q4: Xe | R4: 1500000
F6: #VALUE! | G6: =UPPER(Z22) -> CÔNG SUẤT TỐI ĐA 150 KW/201 HP | K6: Disble !
K7: Disble !
F8: #VALUE! | G8: =UPPER(Z23) -> LAZANG 20 INCH
N9: Hưng
A10: =UPPER(L14) -> VINFAST VF7 PLUS (TC) - THÉP | F10: #VALUE! | G10: =UPPER(Z24) -> TRANG BỊ 08 TÚI KHÍ | Q10: Không xe | R10: 1000000
K11: =V13 -> 949000000 | Q11: Không xe | R11: 1500000 | V11: 0
A12: =UPPER("các chương trình khuyến mãi & giá lăn bánh") -> CÁC CHƯƠNG TRÌNH KHUYẾN MÃI & GIÁ LĂN BÁNH | K12: VIP | Q12: 6000000 | R12: 1500000 | T12: 1500000
C13: GIÁ NIÊM YẾT (ĐÃ BAO GỒM PIN) | G13: GIÁ KHUYẾN MÃI | K13: Dòng xe | L13: VF.7 | N13: Khu vực | O13: Tiền gốc | P13: Tình trạng | Q13: 6000000 | R13: 1500000 | T13: 2000000 | V13: =VLOOKUP(L14,Data!B2:C29,2,0) -> 949000000 | X13: Thu cũ đổi mới | Z13: Lương | AA13: Vinclub
K14: Loại xe : | L14: Vinfast VF7 Plus (TC) - Thép | N14: =DVDK!J4 -> [Hà Tĩnh] Hưng Khê | O14: =DVDK!K4 -> 10000000 | P14: =DVDK!L4 -> 0 | Q14: Xe | T14: 2500000 | V14: =VLOOKUP(L14,Data!F2:G29,2,0) -> 0 | X14: =VLOOKUP(L14,Data!AB2:AC30,2,0) -> 50000000 | Z14: =VLOOKUP(L14,Data!T2:U30,2,0) -> 20000000 | AA14: =VLOOKUP(L14,Data!Z2:AA30,2,0) -> 35000000
C15: =TEXT(V13, "#.##0")& " VNĐ" -> 949.000.000 VNĐ | G15: =V13 -> 949000000 | I15: VNĐ | K15: Trả trước VPBank : | L15: 0.1 | N15: =DVDK!J5 | O15: =DVDK!K5 -> #N/A | P15: =DVDK!L5 -> #N/A | Q15: 7000000 | T15: 3000000 | U15: 531000 | V15: =VLOOKUP(L14,Data!N2:O29,2,0) -> 949000000 | W15: =VLOOKUP(L14,Data!AM2:AN29,2,0) -> 911040000 | Z15: Thưởng | AA15: Biên
N16: =DVDK!J6 | O16: =DVDK!K6 -> #N/A | P16: =DVDK!L6 -> #N/A | Q16: 6000000 | R16: 3300000 | T16: 4000000 | U16: 847000 | V16: =VLOOKUP(L14,Data!AE2:AF29,2,0) -> 0 | Z16: =VLOOKUP(L14,Data!V2:W30,2,0) -> 10000000 | AA16: =VLOOKUP(L14,Data!X2:Y30,2,0) -> 15000000
K17: Trả trước Shinhan : | N17: =DVDK!J7 | O17: =DVDK!K7 -> #N/A | P17: =DVDK!L7 -> #N/A | T17: 4500000 | U17: 944000
C18: CÁC CHƯƠNG TRÌNH KHUYẾN MÃI | L18: 0.2 | N18: =DVDK!J8 | O18: =DVDK!K8 -> #N/A | P18: =DVDK!L8 -> #N/A | T18: 5000000 | U18: 1205000
N19: =DVDK!J9 | T19: 5500000 | U19: 1429000
C20: ● Ưu đãi giảm giá xe 4% | G20: =G15-H20 -> 911040000 | H20: =L31 -> 37960000 | I20: VNĐ | N20: =DVDK!J10 | T20: 6000000 | U20: 3240000 | Z20: =VLOOKUP(L14,Data!BC2:BD30,2,0) -> Thời gian nạp pin (10 - 70%) < 28 phút
C21: ● Ưu đãi 3% dành cho Công An & Quân Đội (nếu có) | G21: =G20-H21 -> 911040000 | I21: =IF(H21="","-","VNĐ") -> -
C22: ● Thu cũ đổi mới (nếu có) | G22: =G21-H22 -> 911040000 | I22: =IF(H22="","-","VNĐ") -> - | T22: 6500000 | V22: =V13-V15 -> 0 | W22: =V13-W15 -> 37960000 | Z22: =VLOOKUP(L14,Data!BE2:BF30,2,0) -> Công suất tối đa 150 kW/201 hp
C23: ● Khách hàng thân thiết (nếu có) | G23: =G22-H23 -> 911040000 | I23: =IF(H23="","-","VNĐ") -> - | K23: VinClub | L23: =AA14 -> 35000000 | V23: =VLOOKUP(L14,Data!AP2:AQ29,2,0) -> Miễn phí sạc 02 năm tại VGreen | Z23: =VLOOKUP(L14,Data!BG2:BH30,2,0) -> Lazang 20 Inch
C24: ● Quy đổi bảo hiểm (áp dụng cho VF3 & VF5) | I24: =IF(H24="","-","VNĐ") -> - | K24: Thưởng | M24: =Z16 -> 10000000 | N24: Tips : Xác định nhu cầu khách hàn | Z24: =VLOOKUP(L14,Data!BI2:BJ30,2,0) -> Trang bị 08 túi khí
C25: ● Ưu đãi khác | G25: =G23-H25 -> 846040000 | H25: 65000000 | I25: =IF(H25="","-","VNĐ") -> VNĐ | K25: Lương | L25: =Z14 -> 20000000 | N25: 1. Anh/ chị có dự định nhận xe trong tháng không hay mình tham khảo trước để em tư vấn anh/ chị luôn ạ ! | Q25: Xe | R25: 5000000 | V25: =VLOOKUP(L14,Data!AR2:AS29,2,0) -> Miễn phí bãi đổ xe và ưu tiên hệ sinh thái VINGROUP | Z25: =VLOOKUP(L14,Data!BK2:BL30,2,0) -> Quãng đường di chuyển dự kiến 496Km
C26: GIÁ CUỐI CÙNG | H26: =$G$25 -> 846040000 | I26: =IF(H26="","-","VNĐ") -> VNĐ | K26: BẢO HIỂM VC XE | L26: 0 | N26: 2. Dạ vậy để tiện cho anh trải nghiệm thực tế trước khi quyết định em đem xe cho Anh/ chị lái thử để cảm nhận luôn nha ! | Q26: 10000000 | R26: 7500000 | T26: 10000000 | V26: =VLOOKUP(L14,Data!AT2:AU29,2,0) -> 0
N27: 3. Trong tuần này Anh/chị có rãnh không ạ, sắp xếp ghé qua Showroom em, sẵn tiện xem xe và em tư vấn kỹ hơn về xe và ngân hàng luôn | Q27: 10000000 | R27: 7000000 | T27: 15000000 | V27: =VLOOKUP(L14,Data!AV2:AW29,2,0) -> 0
K28: Thuế HN tăng thêm : | L28: =U71-G26 -> 0 | N28: Tin nhắn nhanh | R28: 5000000 | T28: 20000000 | V28: =VLOOKUP(L14,Data!AX2:AY29,2,0) -> 0 | W28: =VLOOKUP(L14,Data!AX2:AY29,2,0) -> 0
C29: CHI PHÍ LĂN BÁNH | K29: Thu cũ đổi mới | L29: =X14 -> 50000000 | N29: Dạ mình đã chọn được phiên bản nào chưa ạ, nếu chưa để e tư vấn cho mình thêm để dễ so sánh các bản | R29: 5000000 | T29: 25000000 | U29: 20000000 | V29: =VLOOKUP(L14,Data!#REF!,2,0) -> #REF!
K30: Giá gốc : | L30: =V13 -> 949000000 | N30: Dạ mình tham kháo giá và chương trình khuyến mãi để cân nhắc lấy xe đúng không ạ | Q30: Không xe | R30: 5000000 | T30: 30000000 | U30: 14000000 | V30: =VLOOKUP(L14,Data!AZ2:BA29,2,0) -> 0
C31: 1. Thuế bạ | H31: Miễn phí | K31: Giảm giá : | L31: =IF(L33>L34,L33,L34) -> 37960000 | N31: Mình tham khảo lấy xe lăn bánh biển số về đâu ạ, để e tính cho mình bảng giá chi tiết tham khảo cho dễ | Q31: Xe | R31: 5000000 | T31: 35000000 | U31: 1000000
C32: 2. Lệ phí đăng kí biển số (thu theo biên lai nhà nước) | H32: 20000000 | I32: =IF(H32="","-","VNĐ") -> VNĐ | K32: Điều chỉnh giá : | N32: Mình dự định mua tiền may luôn hay là chọn hình thức trả góp ạ, bên e có hỗ trợ trả góp tối đa lên tới 85% luôn ạ | R32: 5000000 | T32: 40000000 | U32: 200000 | V32: Trắng | W32: - 5L Nguyên liệu
C33: 3. Phí đường bộ (thu theo biên lai nhà nước) | H33: 1560000 | I33: =IF(H33="","-","VNĐ") -> VNĐ | K33: Chương Trình 2024 : | L33: =V22 -> 0 | M33: =L33-L34 -> -37960000 | N33: Lãi Vay các bank : - TRả trước: 20 % trở lên - Lãi suất : + VPBank (Không cần CM thu nhập) : 6.9%/ 2 năm / Thả nổi cỡ 12% (Cần mua BH khoản vay ~ 1.5% giá trị vay) + Lotte (Có CM Thu nhập) : 6.9%/ 2 năm / Thả nổi cỡ 12% (Không cần mua BH khoản vay) + Sacombank : 6.5%/ 2 năm / Thả nổi cỡ 12% (Không cần mua BH khoản vay) + TPBank : 6.5%/ 2 năm / Thả nổi cỡ 12% (cần mua BH khoản vay) Bank nước ngoài như Shinhan : 4.8% / cố định 3 năm Thả nổi cỡ : 10.25% Cần CM thu nhập (NH Nước ngoài không ưu tiên hồ sơ nhỏ nên có thể sẽ cần mua bảo hiêm) | T33: 45000000 | W33: - Bộ lên kiếng tự động
C34: 4. Lệ phí cấp sổ đăng kiểm (thu theo biên lai nhà nước) | H34: 94680 | I34: =IF(H34="","-","VNĐ") -> VNĐ | K34: Chương Trình 2025 : | L34: =W22 -> 37960000 | Q34: Không xe | R34: 5000000 | T34: 50000000 | U34: 0 | V34: Bạc | W34: - Dán phim cách nhiệt Bh 10 Năm
C35: 5. Bảo hiểm trách nhiệm dân sự + người ngồi trên xe | H35: 531000 | I35: =IF(H35="","-","VNĐ") -> VNĐ | K35: Biên nhà máy | L35: =AA16 -> 15000000 | Q35: Không xe | R35: 5000000 | T35: 60000000 | U35: 0.01 | V35: Đỏ | W35: - Lót sàn cách âm , chống cháy
C36: 6. Bảo hiểm vật chất xe/năm | H36: =L26*H26 -> 0 | I36: =IF(H36="","-","VNĐ") -> VNĐ | Q36: Không xe | R36: 5000000 | U36: 0.011 | V36: Đen | W36: - Lót sàn 5D
C37: 7. Dịch vụ đăng ký xe | H37: 3000000 | I37: =IF(H37="","-","VNĐ") -> VNĐ | Q37: Không xe | R37: 5000000 | U37: 0.012 | V37: Vàng cát | W37: - Camera hành trình
C38: TỔNG CỘNG | H38: =SUM($H$32:$H$37) -> 25185680 | I38: =IF(H38="","-","VNĐ") -> VNĐ | K38: TRUE | L38: =IF(OR(L13="VF.9", L13="LIMO"), 1, 0) -> 0 | Q38: 6000000 | R38: 5000000 | U38: 0.013 | V38: Vàng be | W38: - Thẻ nhớ hành trình
C39: TỔNG CỘNG | D39: (GIÁ XE SAU KHUYẾN MÃI + CHI PHÍ ĐĂNG KÝ) | H39: =$H$26+$H$38-$H$24 -> 871225680 | I39: VNĐ | K39: FALSE | Q39: Xe | R39: 5000000 | U39: 0.014 | V39: Xanh | W39: - Tẩu sạc USB
K40: Ngân hàng cho vay : | L40: 375000000 | Q40: 7000000 | R40: 5000000 | U40: 0.015 | V40: Cam | W40: - Phủ gầm
K41: Chênh lệch | L41: =L40-G40 -> 375000000 | Q41: 7000000 | R41: 6000000 | U41: 0.016 | V41: Xanh chuối | W41: - Phủ Ceramic
Q42: 7000000 | R42: 5000000 | U42: 0.017 | W42: - Viền che mưa
...

Sheet Config

Sheet Báo giá
E1: =NOW() -> 45958.743 | F1: Khung thuế HCM | G1: =Q10 -> 0 | I1: TRA CỨU ĐỊA CHỈ ĐĂNG KÝ XE | L1: KHÔNG XE | M1: CP ỨNG | N1: LƯU Ý THUẾ ĐĂNG KÝ XE
D2: Code quà tặng giảm giá : | E2: =RAND()*99999999999 -> 7.9617732e+10 | F2: Lệch | G2: =D19-G1 -> 0 | L2: Không xe | M2: 1500000
G3: ss | L3: Xe | M3: 1500000
A4: BẢNG GIÁ TẠM TÍNH | G4: ss | L4: Không xe | M4: 1000000
A5: - Bảng báo giá chỉ có hiệu lực 24h từ lúc phát hành - Bảng tạm tính các chi phí có liên quan sẽ hoàn lại nếu dư sau khi có hóa đơn - Các mã quà tặng và khuyến mãi sẽ tùy thời điểm nhận xe - Thời gian hiệu lực của mã quà tặng sẽ có hiệu lục 48h sau khi kích hoạt - Lưu ý : phần thanh toán ngân hàng là tạm tính theo mức lãi cao nhất hiện tại, quý khách có đủ điều kiện vay ngân hàng tốt hơn lãi sẽ tốt hơn | F5: =Q7 -> 299000000 | L5: Không xe | M5: 1500000 | Q5: 0
A6: Kính gửi : | B6: =F6 -> VIP | F6: VIP | L6: 6000000 | M6: 1500000 | O6: 1500000
A7: Loại xe : | B7: =G8&" (GIÁ ĐÃ BAO GỒM PIN)" -> Vinfast VF3 (GIÁ ĐÃ BAO GỒM PIN) | F7: Dòng xe | G7: VF.3 | I7: Khu vực | J7: Tiền gốc | K7: Tình trạng | L7: 6000000 | M7: 1500000 | O7: 2000000 | Q7: =VLOOKUP(G8,Data!B2:C29,2,0) -> 299000000 | S7: Thu cũ đổi mới | U7: Lương | V7: Vinclub
A8: GIÁ NIÊM YẾT | C8: =Q7 -> 299000000 | E8: VND | F8: Loại xe : | G8: Vinfast VF3 | I8: =DVDK!J4 -> [Hà Tĩnh] Hưng Khê | J8: =DVDK!K4 -> 10000000 | K8: =DVDK!L4 -> 0 | L8: Xe | O8: 2500000 | Q8: =VLOOKUP(G8,Data!F2:G29,2,0) -> 0 | S8: =VLOOKUP(G8,Data!AB2:AC30,2,0) -> 5000000 | U8: =VLOOKUP(G8,Data!T2:U30,2,0) -> 6000000 | V8: =VLOOKUP(G8,Data!Z2:AA30,2,0) -> 6000000
A9: CÁC CHƯƠNG TRÌNH KHUYẾN MÃI | F9: Trả trước : | G9: 0.15 | I9: =DVDK!J5 | J9: =DVDK!K5 -> #N/A | K9: =DVDK!L5 -> #N/A | L9: 7000000 | O9: 3000000 | P9: 531000 | Q9: =VLOOKUP(G8,Data!N2:O29,2,0) -> 299000000 | R9: =VLOOKUP(G8,Data!AM2:AN29,2,0) -> 287040000 | U9: Thưởng | V9: Biên
A10: =" 1. "&"ƯU ĐÃI GIẢM 4%/ GIÁ XE" -> 1. ƯU ĐÃI GIẢM 4%/ GIÁ XE | D10: =G24-G25 -> 11960000 | E10: =$C$8-D10 -> 287040000 | F10: Tổng tiền đưa trước | G10: =D36 -> 64821200 | I10: =DVDK!J6 | J10: =DVDK!K6 -> #N/A | K10: =DVDK!L6 -> #N/A | L10: 6000000 | M10: 3300000 | O10: 4000000 | P10: 847000 | Q10: =VLOOKUP(G8,Data!AE2:AF29,2,0) -> 0 | U10: =VLOOKUP(G8,Data!V2:W30,2,0) -> 4000000 | V10: =VLOOKUP(G8,Data!X2:Y30,2,0) -> 6000000
A11: =" 2."&" XE VIN 24 (NẾU CÓ)" -> 2. XE VIN 24 (NẾU CÓ) | E11: =E10-D11 -> 287040000 | I11: =DVDK!J7 | J11: =DVDK!K7 -> #N/A | K11: =DVDK!L7 -> #N/A | O11: 4500000 | P11: 944000
A12: =" 2. "&" CHƯƠNG TRÌNH THU CŨ ĐỔI MỚI" -> 2. CHƯƠNG TRÌNH THU CŨ ĐỔI MỚI | E12: =E11-D12 -> 287040000 | I12: =DVDK!J8 | J12: =DVDK!K8 -> #N/A | K12: =DVDK!L8 -> #N/A | O12: 5000000 | P12: 1205000
A13: =" 3. "&" KHÁCH HÀNG THÂN THIẾT" -> 3. KHÁCH HÀNG THÂN THIẾT | E13: =E12-D13 -> 287040000 | I13: =DVDK!J9 | J13: =DVDK!K9 -> #N/A | K13: =DVDK!L9 -> #N/A | O13: 5500000 | P13: 1429000
A14: =" 4."&" CHƯƠNG TRÌNH QUY ĐỔI BẢO HIỂM" -> 4. CHƯƠNG TRÌNH QUY ĐỔI BẢO HIỂM | D14: 6500000 | I14: =DVDK!J10 | J14: =DVDK!K10 -> #N/A | K14: =DVDK!L10 -> #N/A | O14: 6000000 | P14: 3240000
A15: 5. ƯU ĐÃI ĐẶC BIỆT | D15: 4000000 | E15: =E13-D15 -> 283040000 | I15: =DVDK!J11 | J15: =DVDK!K11 -> #N/A | K15: =DVDK!L11 -> #N/A | O15: 6500000 | Q15: =Q7-Q9 -> 0 | R15: =Q7-R9 -> 11960000
A16: GIÁ XE SAU KHUYẾN MÃI | D16: =E15 -> 283040000 | E16: VND | F16: VinClub | G16: =V8 -> 6000000 | Q16: =VLOOKUP(G8,Data!AP2:AQ29,2,0) -> Miễn phí sạc 02 năm tại VGreen
F17: Thưởng | H17: =U10 -> 4000000
A18: STT | B18: CÁC KHOẢN LỆ PHÍ (Hoàn trả lại nếu dư) | D18: THÀNH TIỀN | F18: Lương | G18: =U8 -> 6000000 | L18: Xe | M18: 5000000 | Q18: =VLOOKUP(G8,Data!AR2:AS29,2,0) -> Miễn phí bãi đổ xe và ưu tiên hệ sinh thái VINGROUP
A19: 1 | B19: Thuế trước bạ tam tính (miễn phí) | D19: =(Q8-E19) -> 0 | L19: 10000000 | M19: 7500000 | O19: 10000000 | Q19: =VLOOKUP(G8,Data!AT2:AU29,2,0) -> 0
A20: 2 | B20: Lệ phí đăng kí biển số (thu theo biên lai nhà nước) | D20: 20000000 | L20: 10000000 | M20: 7000000 | O20: 15000000 | Q20: =VLOOKUP(G8,Data!AV2:AW29,2,0) -> 0
A21: 3 | B21: Phí đường bộ (thu theo biên lai nhà nước) | D21: 1560000 | F21: Thuế HN tăng thêm : | G21: =P60-D19 -> 0 | M21: 5000000 | O21: 20000000 | Q21: =VLOOKUP(G8,Data!AX2:AY29,2,0) -> 0 | R21: =VLOOKUP(G8,Data!AX2:AY29,2,0) -> 0
A22: 4 | B22: Lệ phí cấp sổ đăng kiểm (thu theo biên lai nhà nước) | D22: 94680 | F22: Thu cũ đổi mới | G22: =S8 -> 5000000 | M22: 5000000 | O22: 25000000 | P22: 20000000 | Q22: =VLOOKUP(G8,Data!#REF!,2,0) -> #REF!
A23: 5 | B23: Bảo hiểm trách nhiệm dân sự + người ngồi trên xe | D23: =IF(F32=TRUE, P13, IF(F31=TRUE, IF(G31=0, P10, P12), IF(G31=0, P9, P11))) -> 531000 | F23: Giá gốc : | G23: =Q7 -> 299000000 | L23: Không xe | M23: 5000000 | O23: 30000000 | P23: 14000000 | Q23: =VLOOKUP(G8,Data!AZ2:BA29,2,0) -> 0
A24: 6 | B24: Bảo hiểm vật chất xe/năm | C24: 0.013 | D24: =D16*C24 -> 3679520 | F24: Giảm giá : | G24: =IF(G26>G27,G26,G27) -> 11960000 | L24: Xe | M24: 5000000 | O24: 35000000 | P24: 1000000
A25: 7 | B25: Dịch vụ đăng ký xe | D25: 3000000 | F25: Điều chỉnh giá : | M25: 5000000 | O25: 40000000 | P25: 200000 | Q25: Trắng | R25: - 5L Nguyên liệu
A26: 8 | B26: CHƯƠNG TRÌNH GIẢM GIÁ KHÁC | F26: Chương Trình 2024 : | G26: =Q15 -> 0 | H26: =G26-G27 -> -11960000 | O26: 45000000 | R26: - Bộ lên kiếng tự động
A27: Tổng cộng chi phí đăng ký | D27: =SUM(D19:D25) -> 28865200 | F27: Chương Trình 2025 : | G27: =R15 -> 11960000 | L27: Không xe | M27: 5000000 | O27: 50000000 | P27: 0 | Q27: Bạc | R27: - Dán phim cách nhiệt Bh 10 Năm
A28: PHƯƠNG THỨC TRẢ THẲNG | F28: Biên nhà máy | G28: =V10 -> 6000000 | L28: Không xe | M28: 5000000 | O28: 60000000 | P28: 0.01 | Q28: Đỏ | R28: - Lót sàn cách âm , chống cháy
B29: Tiền xe: | D29: =D16 -> 283040000 | L29: Không xe | M29: 5000000 | P29: 0.011 | Q29: Đen | R29: - Lót sàn 5D
B30: Chi phí đăng ký: | D30: =D27 -> 28865200 | L30: Không xe | M30: 5000000 | P30: 0.012 | Q30: Vàng cát | R30: - Camera hành trình
B31: Tổng cộng: | D31: =D29+D30-D14-D26 -> 305405200 | E31: VND | F31: FALSE | G31: =IF(OR(G7="VF.9", G7="LIMO"), 1, 0) -> 0 | L31: 6000000 | M31: 5000000 | P31: 0.013 | Q31: Vàng be | R31: - Thẻ nhớ hành trình
A32: PHƯƠNG THỨC TRẢ QUA NGÂN HÀNG | F32: FALSE | L32: Xe | M32: 5000000 | P32: 0.014 | Q32: Xanh | R32: - Tẩu sạc USB
B33: Vay ngân hàng: | C33: =100%-C34 -> 0.85 | D33: =C33*D16-E33 -> 240584000 | F33: Ngân hàng cho vay : | G33: 375000000 | L33: 7000000 | M33: 5000000 | P33: 0.015 | Q33: Cam | R33: - Phủ gầm
B34: Trả trước: | C34: =G9 -> 0.15 | D34: =D16*G9 -> 42456000 | E34: (1) | F34: Chênh lệch | G34: =G33-D33 -> 134416000 | L34: 7000000 | M34: 6000000 | P34: 0.016 | Q34: Xanh chuối | R34: - Phủ Ceramic
B35: Chi phí đăng ký: | D35: =D27 -> 28865200 | E35: (2) | L35: 7000000 | M35: 5000000 | P35: 0.017 | R35: - Viền che mưa
B36: Tổng cộng (1) + (2) | D36: =D35+D34-D14-D26 -> 64821200 | E36: VND | F36: Tips : Xác định nhu cầu khách hàng | L36: 7000000 | M36: 5000000 | P36: 0.018 | R36: - Bệ bước chân cao cấp
F37: 1. Anh/ chị có dự định nhận xe trong tháng không hay mình tham khảo trước để em tư vấn anh/ chị luôn ạ ! | L37: 7000000 | M37: 5000000 | P37: 0.019 | R37: - Hộp đen kinh doanh
A38: BẢO HÀNH | B38: - Bảo hành 10 năm hoặc 200.000 Km tùy điều kiện nào đến trước | C38: THANH TOÁN NGÂN HÀNG | E38: Số tiền /tháng | L38: 8000000 | M38: 1500000 | P38: 0.02 | R38: - Gói bảo hành nâng cấp 05 năm
C39: - Trả góp 03 năm (dư nợ giảm dần) | E39: =BG03Y!F11 -> 25675199 | F39: 2. Dạ vậy để tiện cho anh trải nghiệm thực tế trước khi quyết định em đem xe cho Anh/ chị lái thử để cảm nhận luôn nha ! | L39: 7000000 | M39: 5000000 | P39: 0.023 | R39: - Thảm taplo
B40: - Bảo hành Pin : 8 Năm | C40: - Trả góp 04 năm (dư nợ giảm dần) | E40: =BG04Y!F11 -> 20387449 | L40: 7000000 | M40: 5000000 | P40: 0.025
...

Sheet Thuế chấp
A1: LỊCH TRẢ NỢ DỰ KIẾN
A2: KHÁCH HÀNG VAY
A3: Giá xe | D3: ='BG New'!H26 -> 846040000
A4: Tổng số tiền vay (VND) | D4: =D3-'BG New'!H66 -> 761436000 | E4: Thời gian ưu đãi (tháng) | G4: 24
A5: Thời gian vay (tháng) | D5: 96 | E5: Lãi tạm tính sau ưu đãi (%/năm) | G5: 0.0925 | L5: 12
A6: Lãi suất ưu đãi (%/năm) | D6: 0.069 | E6: Ngày vay dự kiến | G6: =TODAY() -> 45958 | L6: 24
A7: Số tiền trả trước | D7: =D3-D4+'BG New'!H38 -> 109789680 | E7: =TODAY() -> 45958 | L7: 36
A8: =D5 -> 96 | G8: Tháng | L8: 48
A9: Ngày đóng | B9: Kỳ hạn | C9: Số ngày | D9: Trả gốc | E9: Trả lãi | F9: Total | G9: Dư nợ còn lại | L9: 60
A10: =$G$6 -> 45958 | B10: 0 | G10: =$D4-D10 -> 761436000 | L10: 72
A11: =IF(B10<$D$5,DATE(YEAR(A10),MONTH(A10)+1,DAY(A10)),IF(B10=$D$5,"Tổng","")) -> 45989 | B11: =IF(B10<$D$5,B10+1,"") -> 1 | C11: =IF(B11<>"",A11-A10,"") -> 31 | D11: =IF($B10<$D$5,IF(B10<$G$7,0,$D$4/($D$5-$G$7)),IF($B10=$D$5,$D$4,"")) -> 7931625 | E11: =IF(AND($B11<>"",$B11<=$G$4),$G10*C11*$D$6/360,IF(B11<>"",$G10*C11*$G$5/360,IF(AND(B10<>"",B10=$D$5),SUM($E$10:E10),""))) -> 4524198.9 | F11: =IF(D11<>"",D11+E11,"") -> 12455824 | G11: =IF($B11<>"",G10-D11,"") -> 753504375 | L11: 84
A12: =IF(B11<$D$5,DATE(YEAR(A11),MONTH(A11)+1,DAY(A11)),IF(B11=$D$5,"Tổng","")) -> 46019 | B12: =IF(B11<$D$5,B11+1,"") -> 2 | C12: =IF(B12<>"",A12-A11,"") -> 30 | D12: =IF($B11<$D$5,IF(B11<$G$7,0,$D$4/($D$5-$G$7)),IF($B11=$D$5,$D$4,"")) -> 7931625 | E12: =IF(AND($B12<>"",$B12<=$G$4),$G11*C12*$D$6/360,IF(B12<>"",$G11*C12*$G$5/360,IF(AND(B11<>"",B11=$D$5),SUM($E$10:E11),""))) -> 4332650.2 | F12: =IF(D12<>"",D12+E12,"") -> 12264275 | G12: =IF($B12<>"",G11-D12,"") -> 745572750 | L12: 96
A13: =IF(B12<$D$5,DATE(YEAR(A12),MONTH(A12)+1,DAY(A12)),IF(B12=$D$5,"Tổng","")) -> 46050 | B13: =IF(B12<$D$5,B12+1,"") -> 3 | C13: =IF(B13<>"",A13-A12,"") -> 31 | D13: =IF($B12<$D$5,IF(B12<$G$7,0,$D$4/($D$5-$G$7)),IF($B12=$D$5,$D$4,"")) -> 7931625 | E13: =IF(AND($B13<>"",$B13<=$G$4),$G12*C13*$D$6/360,IF(B13<>"",$G12*C13*$G$5/360,IF(AND(B12<>"",B12=$D$5),SUM($E$10:E12),""))) -> 4429944.8 | F13: =IF(D13<>"",D13+E13,"") -> 12361570 | G13: =IF($B13<>"",G12-D13,"") -> 737641125
A14: =IF(B13<$D$5,DATE(YEAR(A13),MONTH(A13)+1,DAY(A13)),IF(B13=$D$5,"Tổng","")) -> 46081 | B14: =IF(B13<$D$5,B13+1,"") -> 4 | C14: =IF(B14<>"",A14-A13,"") -> 31 | D14: =IF($B13<$D$5,IF(B13<$G$7,0,$D$4/($D$5-$G$7)),IF($B13=$D$5,$D$4,"")) -> 7931625 | E14: =IF(AND($B14<>"",$B14<=$G$4),$G13*C14*$D$6/360,IF(B14<>"",$G13*C14*$G$5/360,IF(AND(B13<>"",B13=$D$5),SUM($E$10:E13),""))) -> 4382817.7 | F14: =IF(D14<>"",D14+E14,"") -> 12314443 | G14: =IF($B14<>"",G13-D14,"") -> 729709500
A15: =IF(B14<$D$5,DATE(YEAR(A14),MONTH(A14)+1,DAY(A14)),IF(B14=$D$5,"Tổng","")) -> 46109 | B15: =IF(B14<$D$5,B14+1,"") -> 5 | C15: =IF(B15<>"",A15-A14,"") -> 28 | D15: =IF($B14<$D$5,IF(B14<$G$7,0,$D$4/($D$5-$G$7)),IF($B14=$D$5,$D$4,"")) -> 7931625 | E15: =IF(AND($B15<>"",$B15<=$G$4),$G14*C15*$D$6/360,IF(B15<>"",$G14*C15*$G$5/360,IF(AND(B14<>"",B14=$D$5),SUM($E$10:E14),""))) -> 3916107.6 | F15: =IF(D15<>"",D15+E15,"") -> 11847733 | G15: =IF($B15<>"",G14-D15,"") -> 721777875
A16: =IF(B15<$D$5,DATE(YEAR(A15),MONTH(A15)+1,DAY(A15)),IF(B15=$D$5,"Tổng","")) -> 46140 | B16: =IF(B15<$D$5,B15+1,"") -> 6 | C16: =IF(B16<>"",A16-A15,"") -> 31 | D16: =IF($B15<$D$5,IF(B15<$G$7,0,$D$4/($D$5-$G$7)),IF($B15=$D$5,$D$4,"")) -> 7931625 | E16: =IF(AND($B16<>"",$B16<=$G$4),$G15*C16*$D$6/360,IF(B16<>"",$G15*C16*$G$5/360,IF(AND(B15<>"",B15=$D$5),SUM($E$10:E15),""))) -> 4288563.5 | F16: =IF(D16<>"",D16+E16,"") -> 12220189 | G16: =IF($B16<>"",G15-D16,"") -> 713846250
A17: =IF(B16<$D$5,DATE(YEAR(A16),MONTH(A16)+1,DAY(A16)),IF(B16=$D$5,"Tổng","")) -> 46170 | B17: =IF(B16<$D$5,B16+1,"") -> 7 | C17: =IF(B17<>"",A17-A16,"") -> 30 | D17: =IF($B16<$D$5,IF(B16<$G$7,0,$D$4/($D$5-$G$7)),IF($B16=$D$5,$D$4,"")) -> 7931625 | E17: =IF(AND($B17<>"",$B17<=$G$4),$G16*C17*$D$6/360,IF(B17<>"",$G16*C17*$G$5/360,IF(AND(B16<>"",B16=$D$5),SUM($E$10:E16),""))) -> 4104615.9 | F17: =IF(D17<>"",D17+E17,"") -> 12036241 | G17: =IF($B17<>"",G16-D17,"") -> 705914625
A18: =IF(B17<$D$5,DATE(YEAR(A17),MONTH(A17)+1,DAY(A17)),IF(B17=$D$5,"Tổng","")) -> 46201 | B18: =IF(B17<$D$5,B17+1,"") -> 8 | C18: =IF(B18<>"",A18-A17,"") -> 31 | D18: =IF($B17<$D$5,IF(B17<$G$7,0,$D$4/($D$5-$G$7)),IF($B17=$D$5,$D$4,"")) -> 7931625 | E18: =IF(AND($B18<>"",$B18<=$G$4),$G17*C18*$D$6/360,IF(B18<>"",$G17*C18*$G$5/360,IF(AND(B17<>"",B17=$D$5),SUM($E$10:E17),""))) -> 4194309.4 | F18: =IF(D18<>"",D18+E18,"") -> 12125934 | G18: =IF($B18<>"",G17-D18,"") -> 697983000
A19: =IF(B18<$D$5,DATE(YEAR(A18),MONTH(A18)+1,DAY(A18)),IF(B18=$D$5,"Tổng","")) -> 46231 | B19: =IF(B18<$D$5,B18+1,"") -> 9 | C19: =IF(B19<>"",A19-A18,"") -> 30 | D19: =IF($B18<$D$5,IF(B18<$G$7,0,$D$4/($D$5-$G$7)),IF($B18=$D$5,$D$4,"")) -> 7931625 | E19: =IF(AND($B19<>"",$B19<=$G$4),$G18*C19*$D$6/360,IF(B19<>"",$G18*C19*$G$5/360,IF(AND(B18<>"",B18=$D$5),SUM($E$10:E18),""))) -> 4013402.3 | F19: =IF(D19<>"",D19+E19,"") -> 11945027 | G19: =IF($B19<>"",G18-D19,"") -> 690051375
A20: =IF(B19<$D$5,DATE(YEAR(A19),MONTH(A19)+1,DAY(A19)),IF(B19=$D$5,"Tổng","")) -> 46262 | B20: =IF(B19<$D$5,B19+1,"") -> 10 | C20: =IF(B20<>"",A20-A19,"") -> 31 | D20: =IF($B19<$D$5,IF(B19<$G$7,0,$D$4/($D$5-$G$7)),IF($B19=$D$5,$D$4,"")) -> 7931625 | E20: =IF(AND($B20<>"",$B20<=$G$4),$G19*C20*$D$6/360,IF(B20<>"",$G19*C20*$G$5/360,IF(AND(B19<>"",B19=$D$5),SUM($E$10:E19),""))) -> 4100055.3 | F20: =IF(D20<>"",D20+E20,"") -> 12031680 | G20: =IF($B20<>"",G19-D20,"") -> 682119750
A21: =IF(B20<$D$5,DATE(YEAR(A20),MONTH(A20)+1,DAY(A20)),IF(B20=$D$5,"Tổng","")) -> 46293 | B21: =IF(B20<$D$5,B20+1,"") -> 11 | C21: =IF(B21<>"",A21-A20,"") -> 31 | D21: =IF($B20<$D$5,IF(B20<$G$7,0,$D$4/($D$5-$G$7)),IF($B20=$D$5,$D$4,"")) -> 7931625 | E21: =IF(AND($B21<>"",$B21<=$G$4),$G20*C21*$D$6/360,IF(B21<>"",$G20*C21*$G$5/360,IF(AND(B20<>"",B20=$D$5),SUM($E$10:E20),""))) -> 4052928.2 | F21: =IF(D21<>"",D21+E21,"") -> 11984553 | G21: =IF($B21<>"",G20-D21,"") -> 674188125
A22: =IF(B21<$D$5,DATE(YEAR(A21),MONTH(A21)+1,DAY(A21)),IF(B21=$D$5,"Tổng","")) -> 46323 | B22: =IF(B21<$D$5,B21+1,"") -> 12 | C22: =IF(B22<>"",A22-A21,"") -> 30 | D22: =IF($B21<$D$5,IF(B21<$G$7,0,$D$4/($D$5-$G$7)),IF($B21=$D$5,$D$4,"")) -> 7931625 | E22: =IF(AND($B22<>"",$B22<=$G$4),$G21*C22*$D$6/360,IF(B22<>"",$G21*C22*$G$5/360,IF(AND(B21<>"",B21=$D$5),SUM($E$10:E21),""))) -> 3876581.7 | F22: =IF(D22<>"",D22+E22,"") -> 11808207 | G22: =IF($B22<>"",G21-D22,"") -> 666256500
A23: =IF(B22<$D$5,DATE(YEAR(A22),MONTH(A22)+1,DAY(A22)),IF(B22=$D$5,"Tổng","")) -> 46354 | B23: =IF(B22<$D$5,B22+1,"") -> 13 | C23: =IF(B23<>"",A23-A22,"") -> 31 | D23: =IF($B22<$D$5,IF(B22<$G$7,0,$D$4/($D$5-$G$7)),IF($B22=$D$5,$D$4,"")) -> 7931625 | E23: =IF(AND($B23<>"",$B23<=$G$4),$G22*C23*$D$6/360,IF(B23<>"",$G22*C23*$G$5/360,IF(AND(B22<>"",B22=$D$5),SUM($E$10:E22),""))) -> 3958674 | F23: =IF(D23<>"",D23+E23,"") -> 11890299 | G23: =IF($B23<>"",G22-D23,"") -> 658324875
A24: =IF(B23<$D$5,DATE(YEAR(A23),MONTH(A23)+1,DAY(A23)),IF(B23=$D$5,"Tổng","")) -> 46384 | B24: =IF(B23<$D$5,B23+1,"") -> 14 | C24: =IF(B24<>"",A24-A23,"") -> 30 | D24: =IF($B23<$D$5,IF(B23<$G$7,0,$D$4/($D$5-$G$7)),IF($B23=$D$5,$D$4,"")) -> 7931625 | E24: =IF(AND($B24<>"",$B24<=$G$4),$G23*C24*$D$6/360,IF(B24<>"",$G23*C24*$G$5/360,IF(AND(B23<>"",B23=$D$5),SUM($E$10:E23),""))) -> 3785368 | F24: =IF(D24<>"",D24+E24,"") -> 11716993 | G24: =IF($B24<>"",G23-D24,"") -> 650393250
... A195: =IF(B194<$D$5,DATE(YEAR(A194),MONTH(A194)+1,DAY(A194)),IF(B194=$D$5,"Tổng","")) | B195: =IF(B194<$D$5,B194+1,"") | C195: =IF(B195<>"",A195-A194,"") | D195: =IF($B194<$D$5,IF(B194<$G$7,0,$D$4/($D$5-$G$7)),IF($B194=$D$5,$D$4,"")) | E195: =IF(AND($B195<>"",$B195<=$G$4),$G194*C195*$D$6/360,IF(B195<>"",$G194*C195*$G$5/360,IF(AND(B194<>"",B194=$D$5),SUM($E$10:E194),""))) | F195: =IF(D195<>"",D195+E195,"") | G195: =IF($B195<>"",G194-D195,"")
A196: =IF(B195<$D$5,DATE(YEAR(A195),MONTH(A195)+1,DAY(A195)),IF(B195=$D$5,"Tổng","")) | B196: =IF(B195<$D$5,B195+1,"") | C196: =IF(B196<>"",A196-A195,"") | D196: =IF($B195<$D$5,$D$4/$D$5,IF($B195=$D$5,$D$4,"")) | E196: =IF(AND($B196<>"",$B196<=$G$4),$G195*C196*$D$6/360,IF(B196<>"",$G195*C196*$G$5/360,IF(AND(B195<>"",B195=$D$5),SUM($E$10:E195),""))) | F196: =IF(D196<>"",D196+E196,"") | G196: =IF($B196<>"",G195-D196,"")
A197: =IF(B196<$D$5,DATE(YEAR(A196),MONTH(A196)+1,DAY(A196)),IF(B196=$D$5,"Tổng","")) | B197: =IF(B196<$D$5,B196+1,"") | C197: =IF(B197<>"",A197-A196,"") | D197: =IF($B196<$D$5,$D$4/$D$5,IF($B196=$D$5,$D$4,"")) | E197: =IF(AND($B197<>"",$B197<=$G$4),$G196*C197*$D$6/360,IF(B197<>"",$G196*C197*$G$5/360,IF(AND(B196<>"",B196=$D$5),SUM($E$10:E196),""))) | F197: =IF(D197<>"",D197+E197,"") | G197: =IF($B197<>"",G196-D197,"")
A198: =IF(B197<$D$5,DATE(YEAR(A197),MONTH(A197)+1,DAY(A197)),IF(B197=$D$5,"Tổng","")) | B198: =IF(B197<$D$5,B197+1,"") | C198: =IF(B198<>"",A198-A197,"") | D198: =IF($B197<$D$5,$D$4/$D$5,IF($B197=$D$5,$D$4,"")) | E198: =IF(AND($B198<>"",$B198<=$G$4),$G197*C198*$D$6/360,IF(B198<>"",$G197*C198*$G$5/360,IF(AND(B197<>"",B197=$D$5),SUM($E$10:E197),""))) | F198: =IF(D198<>"",D198+E198,"") | G198: =IF($B198<>"",G197-D198,"")
A199: =IF(B198<$D$5,DATE(YEAR(A198),MONTH(A198)+1,DAY(A198)),IF(B198=$D$5,"Tổng","")) | B199: =IF(B198<$D$5,B198+1,"") | C199: =IF(B199<>"",A199-A198,"") | D199: =IF($B198<$D$5,$D$4/$D$5,IF($B198=$D$5,$D$4,"")) | E199: =IF(AND($B199<>"",$B199<=$G$4),$G198*C199*$D$6/360,IF(B199<>"",$G198*C199*$G$5/360,IF(AND(B198<>"",B198=$D$5),SUM($E$10:E198),""))) | F199: =IF(D199<>"",D199+E199,"") | G199: =IF($B199<>"",G198-D199,"")
A200: =IF(B199<$D$5,DATE(YEAR(A199),MONTH(A199)+1,DAY(A199)),IF(B199=$D$5,"Tổng","")) | B200: =IF(B199<$D$5,B199+1,"") | C200: =IF(B200<>"",A200-A199,"") | D200: =IF($B199<$D$5,$D$4/$D$5,IF($B199=$D$5,$D$4,"")) | E200: =IF(AND($B200<>"",$B200<=$G$4),$G199*C200*$D$6/360,IF(B200<>"",$G199*C200*$G$5/360,IF(AND(B199<>"",B199=$D$5),SUM($E$10:E199),""))) | F200: =IF(D200<>"",D200+E200,"") | G200: =IF($B200<>"",G199-D200,"")
A201: =IF(B200<$D$5,DATE(YEAR(A200),MONTH(A200)+1,DAY(A200)),IF(B200=$D$5,"Tổng","")) | B201: =IF(B200<$D$5,B200+1,"") | C201: =IF(B201<>"",A201-A200,"") | D201: =IF($B200<$D$5,$D$4/$D$5,IF($B200=$D$5,$D$4,"")) | E201: =IF(AND($B201<>"",$B201<=$G$4),$G200*C201*$D$6/360,IF(B201<>"",$G200*C201*$G$5/360,IF(AND(B200<>"",B200=$D$5),SUM($E$10:E200),""))) | F201: =IF(D201<>"",D201+E201,"") | G201: =IF($B201<>"",G200-D201,"")
A202: =IF(B201<$D$5,DATE(YEAR(A201),MONTH(A201)+1,DAY(A201)),IF(B201=$D$5,"Tổng","")) | B202: =IF(B201<$D$5,B201+1,"") | C202: =IF(B202<>"",A202-A201,"") | D202: =IF($B201<$D$5,$D$4/$D$5,IF($B201=$D$5,$D$4,"")) | E202: =IF(AND($B202<>"",$B202<=$G$4),$G201*C202*$D$6/360,IF(B202<>"",$G201*C202*$G$5/360,IF(AND(B201<>"",B201=$D$5),SUM($E$10:E201),""))) | F202: =IF(D202<>"",D202+E202,"") | G202: =IF($B202<>"",G201-D202,"")
A203: =IF(B202<$D$5,DATE(YEAR(A202),MONTH(A202)+1,DAY(A202)),IF(B202=$D$5,"Tổng","")) | B203: =IF(B202<$D$5,B202+1,"") | C203: =IF(B203<>"",A203-A202,"") | D203: =IF($B202<$D$5,$D$4/$D$5,IF($B202=$D$5,$D$4,"")) | E203: =IF(AND($B203<>"",$B203<=$G$4),$G202*C203*$D$6/360,IF(B203<>"",$G202*C203*$G$5/360,IF(AND(B202<>"",B202=$D$5),SUM($E$10:E202),""))) | F203: =IF(D203<>"",D203+E203,"") | G203: =IF($B203<>"",G202-D203,"")
A204: =IF(B203<$D$5,DATE(YEAR(A203),MONTH(A203)+1,DAY(A203)),IF(B203=$D$5,"Tổng","")) | B204: =IF(B203<$D$5,B203+1,"") | C204: =IF(B204<>"",A204-A203,"") | D204: =IF($B203<$D$5,$D$4/$D$5,IF($B203=$D$5,$D$4,"")) | E204: =IF(AND($B204<>"",$B204<=$G$4),$G203*C204*$D$6/360,IF(B204<>"",$G203*C204*$G$5/360,IF(AND(B203<>"",B203=$D$5),SUM($E$10:E203),""))) | F204: =IF(D204<>"",D204+E204,"") | G204: =IF($B204<>"",G203-D204,"")
A205: =IF(B204<$D$5,DATE(YEAR(A204),MONTH(A204)+1,DAY(A204)),IF(B204=$D$5,"Tổng","")) | B205: =IF(B204<$D$5,B204+1,"") | C205: =IF(B205<>"",A205-A204,"") | D205: =IF($B204<$D$5,$D$4/$D$5,IF($B204=$D$5,$D$4,"")) | E205: =IF(AND($B205<>"",$B205<=$G$4),$G204*C205*$D$6/360,IF(B205<>"",$G204*C205*$G$5/360,IF(AND(B204<>"",B204=$D$5),SUM($E$10:E204),""))) | F205: =IF(D205<>"",D205+E205,"") | G205: =IF($B205<>"",G204-D205,"")
A206: =IF(B205<$D$5,DATE(YEAR(A205),MONTH(A205)+1,DAY(A205)),IF(B205=$D$5,"Tổng","")) | B206: =IF(B205<$D$5,B205+1,"") | C206: =IF(B206<>"",A206-A205,"") | D206: =IF($B205<$D$5,$D$4/$D$5,IF($B205=$D$5,$D$4,"")) | E206: =IF(AND($B206<>"",$B206<=$G$4),$G205*C206*$D$6/360,IF(B206<>"",$G205*C206*$G$5/360,IF(AND(B205<>"",B205=$D$5),SUM($E$10:E205),""))) | F206: =IF(D206<>"",D206+E206,"") | G206: =IF($B206<>"",G205-D206,"")
A207: =IF(B206<$D$5,DATE(YEAR(A206),MONTH(A206)+1,DAY(A206)),IF(B206=$D$5,"Tổng","")) | B207: =IF(B206<$D$5,B206+1,"") | C207: =IF(B207<>"",A207-A206,"") | D207: =IF($B206<$D$5,$D$4/$D$5,IF($B206=$D$5,$D$4,"")) | E207: =IF(AND($B207<>"",$B207<=$G$4),$G206*C207*$D$6/360,IF(B207<>"",$G206*C207*$G$5/360,IF(AND(B206<>"",B206=$D$5),SUM($E$10:E206),""))) | F207: =IF(D207<>"",D207+E207,"") | G207: =IF($B207<>"",G206-D207,"")
... A251: =IF(B250<$D$5,DATE(YEAR(A250),MONTH(A250)+1,DAY(A250)),IF(B250=$D$5,"Tổng","")) | B251: =IF(B250<$D$5,B250+1,"") | C251: =IF(B251<>"",A251-A250,"") | D251: =IF($B250<$D$5,$D$4/$D$5,IF($B250=$D$5,$D$4,"")) | E251: =IF(AND($B251<>"",$B251<=$G$4),$G250*C251*$D$6/360,IF(B251<>"",$G250*C251*$G$5/360,IF(AND(B250<>"",B250=$D$5),SUM($E$10:E250),""))) | F251: =IF(D251<>"",D251+E251,"") | G251: =IF($B251<>"",G250-D251,"")
A252: =IF(B251<$D$5,DATE(YEAR(A251),MONTH(A251)+1,DAY(A251)),IF(B251=$D$5,"Tổng","")) | B252: =IF(B251<$D$5,B251+1,"") | C252: =IF(B252<>"",A252-A251,"") | D252: =IF($B251<$D$5,$D$4/$D$5,IF($B251=$D$5,$D$4,"")) | E252: =IF(AND($B252<>"",$B252<=$G$4),$G251*C252*$D$6/360,IF(B252<>"",$G251*C252*$G$5/360,IF(AND(B252<>"",B251=$D$5),SUM($E$10:E251),""))) | F252: =IF(D252<>"",D252+E252,"") | G252: =IF($B252<>"",G251-D252,"")
A253: =IF(B252<$D$5,DATE(YEAR(A252),MONTH(A252)+1,DAY(A252)),IF(B252=$D$5,"Tổng","")) | B253: =IF(B252<$D$5,B252+1,"") | C253: =IF(B253<>"",A253-A252,"") | D253: =IF($B252<$D$5,$D$4/$D$5,IF($B252=$D$5,$D$4,"")) | E253: =IF(AND($B253<>"",$B253<=$G$4),$G252*C253*$D$6/360,IF(B253<>"",$G252*C253*$G$5/360,IF(AND(B253<>"",B252=$D$5),SUM($E$10:E252),""))) | F253: =IF(D253<>"",D253+E253,"") | G253: =IF($B253<>"",G252-D253,"")
...

Sheet Bank 2
A1: LỊCH TRẢ NỢ DỰ KIẾN | H1: LỊCH TRẢ NỢ DỰ KIẾN | O1: LỊCH TRẢ NỢ DỰ KIẾN | V1: LỊCH TRẢ NỢ DỰ KIẾN | AC1: LỊCH TRẢ NỢ DỰ KIẾN | AJ1: LỊCH TRẢ NỢ DỰ KIẾN
A2: KHÁCH HÀNG VAY | H2: KHÁCH HÀNG VAY | O2: KHÁCH HÀNG VAY | V2: KHÁCH HÀNG VAY | AC2: KHÁCH HÀNG VAY | AJ2: KHÁCH HÀNG VAY
A3: Giá xe | D3: ='Thuế chấp'!$D$3 -> 846040000 | H3: Giá xe | K3: ='Thuế chấp'!$D$3 -> 846040000 | O3: Giá xe | R3: ='Thuế chấp'!$D$3 -> 846040000 | V3: Giá xe | Y3: ='Thuế chấp'!$D$3 -> 846040000 | AC3: Giá xe | AF3: ='Thuế chấp'!$D$3 -> 846040000 | AJ3: Giá xe | AM3: ='Thuế chấp'!$D$3 -> 846040000
A4: Tổng số tiền vay (VND) | D4: ='BG New'!H70 -> 676832000 | E4: Thời gian ưu đãi (tháng) | G4: 36 | H4: Tổng số tiền vay (VND) | K4: =D4 -> 676832000 | L4: Thời gian ưu đãi (tháng) | N4: 36 | O4: Tổng số tiền vay (VND) | R4: =K4 -> 676832000 | S4: Thời gian ưu đãi (tháng) | U4: 36 | V4: Tổng số tiền vay (VND) | Y4: =R4 -> 676832000 | Z4: Thời gian ưu đãi (tháng) | AB4: 36 | AC4: Tổng số tiền vay (VND) | AF4: =Y4 -> 676832000 | AG4: Thời gian ưu đãi (tháng) | AI4: 36 | AJ4: Tổng số tiền vay (VND) | AM4: =AF4 -> 676832000 | AN4: Thời gian ưu đãi (tháng) | AP4: 36
A5: Thời gian vay (tháng) | D5: 36 | E5: Lãi tạm tính sau ưu đãi (%/năm) | G5: 0.1025 | H5: Thời gian vay (tháng) | K5: 48 | L5: Lãi tạm tính sau ưu đãi (%/năm) | N5: 0.1025 | O5: Thời gian vay (tháng) | R5: 60 | S5: Lãi tạm tính sau ưu đãi (%/năm) | U5: 0.1025 | V5: Thời gian vay (tháng) | Y5: 72 | Z5: Lãi tạm tính sau ưu đãi (%/năm) | AB5: 0.1025 | AC5: Thời gian vay (tháng) | AF5: 84 | AG5: Lãi tạm tính sau ưu đãi (%/năm) | AI5: 0.1025 | AJ5: Thời gian vay (tháng) | AM5: 96 | AN5: Lãi tạm tính sau ưu đãi (%/năm) | AP5: 0.1025
A6: Lãi suất ưu đãi (%/năm) | D6: 0.048 | E6: Ngày vay dự kiến | G6: =TODAY() -> 45958 | H6: Lãi suất ưu đãi (%/năm) | K6: 0.048 | L6: Ngày vay dự kiến | N6: =TODAY() -> 45958 | O6: Lãi suất ưu đãi (%/năm) | R6: 0.048 | S6: Ngày vay dự kiến | U6: =TODAY() -> 45958 | V6: Lãi suất ưu đãi (%/năm) | Y6: 0.048 | Z6: Ngày vay dự kiến | AB6: =TODAY() -> 45958 | AC6: Lãi suất ưu đãi (%/năm) | AF6: 0.048 | AG6: Ngày vay dự kiến | AI6: =TODAY() -> 45958 | AJ6: Lãi suất ưu đãi (%/năm) | AM6: 0.048 | AN6: Ngày vay dự kiến | AP6: =TODAY() -> 45958
A7: Số tiền trả trước | D7: ='Báo giá'!$D$36 -> 64821200 | E7: =TODAY() -> 45958 | H7: Số tiền trả trước | K7: ='Báo giá'!$D$36 -> 64821200 | L7: =TODAY() -> 45958 | O7: Số tiền trả trước | R7: ='Báo giá'!$D$36 -> 64821200 | S7: =TODAY() -> 45958 | V7: Số tiền trả trước | Y7: ='Báo giá'!$D$36 -> 64821200 | Z7: =TODAY() -> 45958 | AC7: Số tiền trả trước | AF7: ='Báo giá'!$D$36 -> 64821200 | AG7: =TODAY() -> 45958 | AJ7: Số tiền trả trước | AM7: ='Báo giá'!$D$36 -> 64821200 | AN7: =TODAY() -> 45958
A8: =D5 -> 36 | G8: Tháng | H8: =K5 -> 48 | N8: Tháng | O8: =R5 -> 60 | U8: Tháng | V8: =Y5 -> 72 | AB8: Tháng | AC8: =AF5 -> 84 | AI8: Tháng | AJ8: =AM5 -> 96 | AP8: Tháng
A9: Ngày đóng | B9: Kỳ hạn | C9: Số ngày | D9: Trả gốc | E9: Trả lãi | F9: Total | G9: Dư nợ còn lại | H9: Ngày đóng | I9: Kỳ hạn | J9: Số ngày | K9: Trả gốc | L9: Trả lãi | M9: Total | N9: Dư nợ còn lại | O9: Ngày đóng | P9: Kỳ hạn | Q9: Số ngày | R9: Trả gốc | S9: Trả lãi | T9: Total | U9: Dư nợ còn lại | V9: Ngày đóng | W9: Kỳ hạn | X9: Số ngày | Y9: Trả gốc | Z9: Trả lãi | AA9: Total | AB9: Dư nợ còn lại | AC9: Ngày đóng | AD9: Kỳ hạn | AE9: Số ngày | AF9: Trả gốc | AG9: Trả lãi | AH9: Total | AI9: Dư nợ còn lại | AJ9: Ngày đóng | AK9: Kỳ hạn | AL9: Số ngày | AM9: Trả gốc | AN9: Trả lãi | AO9: Total | AP9: Dư nợ còn lại
A10: =$G$6 -> 45958 | B10: 0 | G10: =D4-D10 -> 676832000 | H10: =$G$6 -> 45958 | I10: 1 | N10: =K4-K10 -> 676832000 | O10: =$G$6 -> 45958 | P10: 2 | U10: =R4-R10 -> 676832000 | V10: =$G$6 -> 45958 | W10: 3 | AB10: =Y4-Y10 -> 676832000 | AC10: =$G$6 -> 45958 | AD10: 4 | AI10: =AF4-AF10 -> 676832000 | AJ10: =$G$6 -> 45958 | AK10: 5 | AP10: =AM4-AM10 -> 676832000
A11: =IF(B10<$D$5,DATE(YEAR(A10),MONTH(A10)+1,DAY(A10)),IF(B10=$D$5,"Tổng","")) -> 45989 | B11: =IF($B$10<$D$5,$B$10+1,"") -> 1 | C11: =IF($B$11<>"",$A$11-$A$10,"") -> 31 | D11: =IF(B10<D5,IF(B10<G7,0,D4/(D5-G7)),IF(B10=D5,D4,"")) -> 18800889 | E11: =IF(AND(B11<>"",B11<=G4),G10*C11*D6/360,IF(B11<>"",G10*C11*G5/360,IF(AND(B10<>"",B10=D5),SUM(E10:E10),""))) -> 2797572.3 | F11: =IF(D11<>"",D11+E11,"") -> 21598461 | G11: =IF(B11<>"",G10-D11,"") -> 6.5803111e+08 | H11: =IF(I10<$D$5,DATE(YEAR(H10),MONTH(H10)+1,DAY(H10)),IF(I10=$D$5,"Tổng","")) -> 45989 | I11: =IF($B$10<$D$5,$B$10+1,"") -> 1 | J11: =IF($B$11<>"",$A$11-$A$10,"") -> 31 | K11: =IF(I10<K5,IF(I10<N7,0,K4/(K5-N7)),IF(I10=K5,K4,"")) -> 14100667 | L11: =IF(AND(I11<>"",I11<=N4),N10*J11*K6/360,IF(I11<>"",N10*J11*N5/360,IF(AND(I10<>"",I10=K5),SUM(L10:L10),""))) -> 2797572.3 | M11: =IF(K11<>"",K11+L11,"") -> 16898239 | N11: =IF(I11<>"",N10-K11,"") -> 6.6273133e+08 | O11: =IF(P10<$D$5,DATE(YEAR(O10),MONTH(O10)+1,DAY(O10)),IF(P10=$D$5,"Tổng","")) -> 45989 | P11: =IF($B$10<$D$5,$B$10+1,"") -> 1 | Q11: =IF($B$11<>"",$A$11-$A$10,"") -> 31 | R11: =IF(P10<R5,IF(P10<U7,0,R4/(R5-U7)),IF(P10=R5,R4,"")) -> 11280533 | S11: =IF(AND(P11<>"",P11<=U4),U10*Q11*R6/360,IF(P11<>"",U10*Q11*U5/360,IF(AND(P10<>"",P10=R5),SUM(S10:S10),""))) -> 2797572.3 | T11: =IF(R11<>"",R11+S11,"") -> 14078106 | U11: =IF(P11<>"",U10-R11,"") -> 6.6555147e+08 | V11: =IF(W10<$D$5,DATE(YEAR(V10),MONTH(V10)+1,DAY(V10)),IF(W10=$D$5,"Tổng","")) -> 45989 | W11: =IF($B$10<$D$5,$B$10+1,"") -> 1 | X11: =IF($B$11<>"",$A$11-$A$10,"") -> 31 | Y11: =IF(W10<Y5,IF(W10<AB7,0,Y4/(Y5-AB7)),IF(W10=Y5,Y4,"")) -> 9400444.4 | Z11: =IF(AND(W11<>"",W11<=AB4),AB10*X11*Y6/360,IF(W11<>"",AB10*X11*AB5/360,IF(AND(W10<>"",W10=Y5),SUM(Z10:Z10),""))) -> 2797572.3 | AA11: =IF(Y11<>"",Y11+Z11,"") -> 12198017 | AB11: =IF(W11<>"",AB10-Y11,"") -> 6.6743156e+08 | AC11: =IF(AD10<$D$5,DATE(YEAR(AC10),MONTH(AC10)+1,DAY(AC10)),IF(AD10=$D$5,"Tổng","")) -> 45989 | AD11: =IF($B$10<$D$5,$B$10+1,"") -> 1 | AE11: =IF($B$11<>"",$A$11-$A$10,"") -> 31 | AF11: =IF(AD10<AF5,IF(AD10<AI7,0,AF4/(AF5-AI7)),IF(AD10=AF5,AF4,"")) -> 8057523.8 | AG11: =IF(AND(AD11<>"",AD11<=AI4),AI10*AE11*AF6/360,IF(AD11<>"",AI10*AE11*AI5/360,IF(AND(AD10<>"",AD10=AF5),SUM(AG10:AG10),""))) -> 2797572.3 | AH11: =IF(AF11<>"",AF11+AG11,"") -> 10855096 | AI11: =IF(AD11<>"",AI10-AF11,"") -> 6.6877448e+08 | AJ11: =IF(AK10<$D$5,DATE(YEAR(AJ10),MONTH(AJ10)+1,DAY(AJ10)),IF(AK10=$D$5,"Tổng","")) -> 45989 | AK11: =IF($B$10<$D$5,$B$10+1,"") -> 1 | AL11: =IF($B$11<>"",$A$11-$A$10,"") -> 31 | AM11: =IF(AK10<AM5,IF(AK10<AP7,0,AM4/(AM5-AP7)),IF(AK10=AM5,AM4,"")) -> 7050333.3 | AN11: =IF(AND(AK11<>"",AK11<=AP4),AP10*AL11*AM6/360,IF(AK11<>"",AP10*AL11*AP5/360,IF(AND(AK10<>"",AK10=AM5),SUM(AN10:AN10),""))) -> 2797572.3 | AO11: =IF(AM11<>"",AM11+AN11,"") -> 9847905.6 | AP11: =IF(AK11<>"",AP10-AM11,"") -> 6.6978167e+08

Sheet LS_Custom
A1: LỊCH TRẢ NỢ DỰ KIẾN
A2: KHÁCH HÀNG VAY
A3: Giá xe | D3: -
A4: Tổng số tiền vay (VND) | D4: 35000000 | E4: Thời gian ưu đãi (tháng) | G4: 24
A5: Thời gian vay (tháng) | D5: 36 | E5: Lãi dự kiến sau ưu đãi (%/năm) | G5: 0.0925
A6: Lãi suất ưu đãi (%/năm) | D6: 0.32 | E6: Ngày vay dự kiến | G6: =TODAY() -> 45958 | J6: =1192174*24 -> 28612176
A7: Số tiền vay | C7: =D4 -> 35000000 | E7: Thời gian ân hạn gốc (tháng) | G7: 0 | J7: 12
A8: =D5 -> 36 | G8: Tháng | J8: =J7+12 -> 24
A9: Ngày đóng | B9: Kỳ hạn | C9: Số ngày | D9: Trả gốc | E9: Trả lãi | F9: Total | G9: Dư nợ còn lại
A10: =$G$6 -> 45958 | B10: 0 | G10: =$D4-D10 -> 35000000
A11: =IF(B10<$D$5,DATE(YEAR(A10),MONTH(A10)+1,DAY(A10)),IF(B10=$D$5,"Tổng","")) -> 45989 | B11: =IF(B10<$D$5,B10+1,"") -> 1 | C11: =IF(B11<>"",A11-A10,"") -> 31 | D11: =IF($B10<$D$5,IF(B10<$G$7,0,$D$4/($D$5-$G$7)),IF($B10=$D$5,$D$4,"")) -> 972222.22 | E11: =IF(AND($B11<>"",$B11<=$G$4),$G10*C11*$D$6/360,IF(B11<>"",$G10*C11*$G$5/360,IF(AND(B10<>"",B10=$D$5),SUM($E$10:E10),""))) -> 964444.44 | F11: =IF(D11<>"",D11+E11,"") -> 1936666.7 | G11: =IF($B11<>"",G10-D11,"") -> 34027778 | J11: =J10+12 -> 12
A12: =IF(B11<$D$5,DATE(YEAR(A11),MONTH(A11)+1,DAY(A11)),IF(B11=$D$5,"Tổng","")) -> 46019 | B12: =IF(B11<$D$5,B11+1,"") -> 2 | C12: =IF(B12<>"",A12-A11,"") -> 30 | D12: =IF($B11<$D$5,IF(B11<$G$7,0,$D$4/($D$5-$G$7)),IF($B11=$D$5,$D$4,"")) -> 972222.22 | E12: =IF(AND($B12<>"",$B12<=$G$4),$G11*C12*$D$6/360,IF(B12<>"",$G11*C12*$G$5/360,IF(AND(B11<>"",B11=$D$5),SUM($E$10:E11),""))) -> 907407.41 | F12: =IF(D12<>"",D12+E12,"") -> 1879629.6 | G12: =IF($B12<>"",G11-D12,"") -> 33055556 | J12: =J11+12 -> 24
A13: =IF(B12<$D$5,DATE(YEAR(A12),MONTH(A12)+1,DAY(A12)),IF(B12=$D$5,"Tổng","")) -> 46050 | B13: =IF(B12<$D$5,B12+1,"") -> 3 | C13: =IF(B13<>"",A13-A12,"") -> 31 | D13: =IF($B12<$D$5,IF(B12<$G$7,0,$D$4/($D$5-$G$7)),IF($B12=$D$5,$D$4,"")) -> 972222.22 | E13: =IF(AND($B13<>"",$B13<=$G$4),$G12*C13*$D$6/360,IF(B13<>"",$G12*C13*$G$5/360,IF(AND(B12<>"",B12=$D$5),SUM($E$10:E12),""))) -> 910864.2 | F13: =IF(D13<>"",D13+E13,"") -> 1883086.4 | G13: =IF($B13<>"",G12-D13,"") -> 32083333 | J13: =J12+12 -> 36
A14: =IF(B13<$D$5,DATE(YEAR(A13),MONTH(A13)+1,DAY(A13)),IF(B13=$D$5,"Tổng","")) -> 46081 | B14: =IF(B13<$D$5,B13+1,"") -> 4 | C14: =IF(B14<>"",A14-A13,"") -> 31 | D14: =IF($B13<$D$5,IF(B13<$G$7,0,$D$4/($D$5-$G$7)),IF($B13=$D$5,$D$4,"")) -> 972222.22 | E14: =IF(AND($B14<>"",$B14<=$G$4),$G13*C14*$D$6/360,IF(B14<>"",$G13*C14*$G$5/360,IF(AND(B13<>"",B13=$D$5),SUM($E$10:E13),""))) -> 884074.07 | F14: =IF(D14<>"",D14+E14,"") -> 1856296.3 | G14: =IF($B14<>"",G13-D14,"") -> 31111111 | J14: =J13+12 -> 48
A15: =IF(B14<$D$5,DATE(YEAR(A14),MONTH(A14)+1,DAY(A14)),IF(B14=$D$5,"Tổng","")) -> 46109 | B15: =IF(B14<$D$5,B14+1,"") -> 5 | C15: =IF(B15<>"",A15-A14,"") -> 28 | D15: =IF($B14<$D$5,IF(B14<$G$7,0,$D$4/($D$5-$G$7)),IF($B14=$D$5,$D$4,"")) -> 972222.22 | E15: =IF(AND($B15<>"",$B15<=$G$4),$G14*C15*$D$6/360,IF(B15<>"",$G14*C15*$G$5/360,IF(AND(B14<>"",B14=$D$5),SUM($E$10:E14),""))) -> 774320.99 | F15: =IF(D15<>"",D15+E15,"") -> 1746543.2 | G15: =IF($B15<>"",G14-D15,"") -> 30138889
A16: =IF(B15<$D$5,DATE(YEAR(A15),MONTH(A15)+1,DAY(A15)),IF(B15=$D$5,"Tổng","")) -> 46140 | B16: =IF(B15<$D$5,B15+1,"") -> 6 | C16: =IF(B16<>"",A16-A15,"") -> 31 | D16: =IF($B15<$D$5,IF(B15<$G$7,0,$D$4/($D$5-$G$7)),IF($B15=$D$5,$D$4,"")) -> 972222.22 | E16: =IF(AND($B16<>"",$B16<=$G$4),$G15*C16*$D$6/360,IF(B16<>"",$G15*C16*$G$5/360,IF(AND(B15<>"",B15=$D$5),SUM($E$10:E15),""))) -> 830493.83 | F16: =IF(D16<>"",D16+E16,"") -> 1802716 | G16: =IF($B16<>"",G15-D16,"") -> 29166667
A17: =IF(B16<$D$5,DATE(YEAR(A16),MONTH(A16)+1,DAY(A16)),IF(B16=$D$5,"Tổng","")) -> 46170 | B17: =IF(B16<$D$5,B16+1,"") -> 7 | C17: =IF(B17<>"",A17-A16,"") -> 30 | D17: =IF($B16<$D$5,IF(B16<$G$7,0,$D$4/($D$5-$G$7)),IF($B16=$D$5,$D$4,"")) -> 972222.22 | E17: =IF(AND($B17<>"",$B17<=$G$4),$G16*C17*$D$6/360,IF(B17<>"",$G16*C17*$G$5/360,IF(AND(B16<>"",B16=$D$5),SUM($E$10:E16),""))) -> 777777.78 | F17: =IF(D17<>"",D17+E17,"") -> 1750000 | G17: =IF($B17<>"",G16-D17,"") -> 28194444
A18: =IF(B17<$D$5,DATE(YEAR(A17),MONTH(A17)+1,DAY(A17)),IF(B17=$D$5,"Tổng","")) -> 46201 | B18: =IF(B17<$D$5,B17+1,"") -> 8 | C18: =IF(B18<>"",A18-A17,"") -> 31 | D18: =IF($B17<$D$5,IF(B17<$G$7,0,$D$4/($D$5-$G$7)),IF($B17=$D$5,$D$4,"")) -> 972222.22 | E18: =IF(AND($B18<>"",$B18<=$G$4),$G17*C18*$D$6/360,IF(B18<>"",$G17*C18*$G$5/360,IF(AND(B17<>"",B17=$D$5),SUM($E$10:E17),""))) -> 776913.58 | F18: =IF(D18<>"",D18+E18,"") -> 1749135.8 | G18: =IF($B18<>"",G17-D18,"") -> 27222222
A19: =IF(B18<$D$5,DATE(YEAR(A18),MONTH(A18)+1,DAY(A18)),IF(B18=$D$5,"Tổng","")) -> 46231 | B19: =IF(B18<$D$5,B18+1,"") -> 9 | C19: =IF(B19<>"",A19-A18,"") -> 30 | D19: =IF($B18<$D$5,IF(B18<$G$7,0,$D$4/($D$5-$G$7)),IF($B18=$D$5,$D$4,"")) -> 972222.22 | E19: =IF(AND($B19<>"",$B19<=$G$4),$G18*C19*$D$6/360,IF(B19<>"",$G18*C19*$G$5/360,IF(AND(B18<>"",B18=$D$5),SUM($E$10:E18),""))) -> 725925.93 | F19: =IF(D19<>"",D19+E19,"") -> 1698148.1 | G19: =IF($B19<>"",G18-D19,"") -> 26250000
A20: =IF(B19<$D$5,DATE(YEAR(A19),MONTH(A19)+1,DAY(A19)),IF(B19=$D$5,"Tổng","")) -> 46262 | B20: =IF(B19<$D$5,B19+1,"") -> 10 | C20: =IF(B20<>"",A20-A19,"") -> 31 | D20: =IF($B19<$D$5,IF(B19<$G$7,0,$D$4/($D$5-$G$7)),IF($B19=$D$5,$D$4,"")) -> 972222.22 | E20: =IF(AND($B20<>"",$B20<=$G$4),$G19*C20*$D$6/360,IF(B20<>"",$G19*C20*$G$5/360,IF(AND(B19<>"",B19=$D$5),SUM($E$10:E19),""))) -> 723333.33 | F20: =IF(D20<>"",D20+E20,"") -> 1695555.6 | G20: =IF($B20<>"",G19-D20,"") -> 25277778
A21: =IF(B20<$D$5,DATE(YEAR(A20),MONTH(A20)+1,DAY(A20)),IF(B20=$D$5,"Tổng","")) -> 46293 | B21: =IF(B20<$D$5,B20+1,"") -> 11 | C21: =IF(B21<>"",A21-A20,"") -> 31 | D21: =IF($B20<$D$5,IF(B20<$G$7,0,$D$4/($D$5-$G$7)),IF($B20=$D$5,$D$4,"")) -> 972222.22 | E21: =IF(AND($B21<>"",$B21<=$G$4),$G20*C21*$D$6/360,IF(B21<>"",$G20*C21*$G$5/360,IF(AND(B20<>"",B20=$D$5),SUM($E$10:E20),""))) -> 696543.21 | F21: =IF(D21<>"",D21+E21,"") -> 1668765.4 | G21: =IF($B21<>"",G20-D21,"") -> 24305556
A22: =IF(B21<$D$5,DATE(YEAR(A21),MONTH(A21)+1,DAY(A21)),IF(B21=$D$5,"Tổng","")) -> 46323 | B22: =IF(B21<$D$5,B21+1,"") -> 12 | C22: =IF(B22<>"",A22-A21,"") -> 30 | D22: =IF($B21<$D$5,IF(B21<$G$7,0,$D$4/($D$5-$G$7)),IF($B21=$D$5,$D$4,"")) -> 972222.22 | E22: =IF(AND($B22<>"",$B22<=$G$4),$G21*C22*$D$6/360,IF(B22<>"",$G21*C22*$G$5/360,IF(AND(B21<>"",B21=$D$5),SUM($E$10:E21),""))) -> 648148.15 | F22: =IF(D22<>"",D22+E22,"") -> 1620370.4 | G22: =IF($B22<>"",G21-D22,"") -> 23333333
A23: =IF(B22<$D$5,DATE(YEAR(A22),MONTH(A22)+1,DAY(A22)),IF(B22=$D$5,"Tổng","")) -> 46354 | B23: =IF(B22<$D$5,B22+1,"") -> 13 | C23: =IF(B23<>"",A23-A22,"") -> 31 | D23: =IF($B22<$D$5,IF(B22<$G$7,0,$D$4/($D$5-$G$7)),IF($B22=$D$5,$D$4,"")) -> 972222.22 | E23: =IF(AND($B23<>"",$B23<=$G$4),$G22*C23*$D$6/360,IF(B23<>"",$G22*C23*$G$5/360,IF(AND(B22<>"",B22=$D$5),SUM($E$10:E22),""))) -> 642962.96 | F23: =IF(D23<>"",D23+E23,"") -> 1615185.2 | G23: =IF($B23<>"",G22-D23,"") -> 22361111
A24: =IF(B23<$D$5,DATE(YEAR(A23),MONTH(A23)+1,DAY(A23)),IF(B23=$D$5,"Tổng","")) -> 46384 | B24: =IF(B23<$D$5,B23+1,"") -> 14 | C24: =IF(B24<>"",A24-A23,"") -> 30 | D24: =IF($B23<$D$5,IF(B23<$G$7,0,$D$4/($D$5-$G$7)),IF($B23=$D$5,$D$4,"")) -> 972222.22 | E24: =IF(AND($B24<>"",$B24<=$G$4),$G23*C24*$D$6/360,IF(B24<>"",$G23*C24*$G$5/360,IF(AND(B23<>"",B23=$D$5),SUM($E$10:E23),""))) -> 596296.3 | F24: =IF(D24<>"",D24+E24,"") -> 1568518.5 | G24: =IF($B24<>"",G23-D24,"") -> 21388889
A25: =IF(B24<$D$5,DATE(YEAR(A24),MONTH(A24)+1,DAY(A24)),IF(B24=$D$5,"Tổng","")) -> 46415 | B25: =IF(B24<$D$5,B24+1,"") -> 15 | C25: =IF(B25<>"",A25-A24,"") -> 31 | D25: =IF($B24<$D$5,IF(B24<$G$7,0,$D$4/($D$5-$G$7)),IF($B24=$D$5,$D$4,"")) -> 972222.22 | E25: =IF(AND($B25<>"",$B25<=$G$4),$G24*C25*$D$6/360,IF(B25<>"",$G24*C25*$G$5/360,IF(AND(B24<>"",B24=$D$5),SUM($E$10:E24),""))) -> 589382.72 | F25: =IF(D25<>"",D25+E25,"") -> 1561604.9 | G25: =IF($B25<>"",G24-D25,"") -> 20416667
A26: =IF(B25<$D$5,DATE(YEAR(A25),MONTH(A25)+1,DAY(A25)),IF(B25=$D$5,"Tổng","")) -> 46446 | B26: =IF(B25<$D$5,B25+1,"") -> 16 | C26: =IF(B26<>"",A26-A25,"") -> 31 | D26: =IF($B25<$D$5,IF(B25<$G$7,0,$D$4/($D$5-$G$7)),IF($B25=$D$5,$D$4,"")) -> 972222.22 | E26: =IF(AND($B26<>"",$B26<=$G$4),$G25*C26*$D$6/360,IF(B26<>"",$G25*C26*$G$5/360,IF(AND(B25<>"",B25=$D$5),SUM($E$10:E25),""))) -> 562592.59 | F26: =IF(D26<>"",D26+E26,"") -> 1534814.8 | G26: =IF($B26<>"",G25-D26,"") -> 19444444
... A195: =IF(B194<$D$5,DATE(YEAR(A194),MONTH(A194)+1,DAY(A194)),IF(B194=$D$5,"Tổng","")) | B195: =IF(B194<$D$5,B194+1,"") | C195: =IF(B195<>"",A195-A194,"") | D195: =IF($B194<$D$5,IF(B194<$G$7,0,$D$4/($D$5-$G$7)),IF($B194=$D$5,$D$4,"")) | E195: =IF(AND($B195<>"",$B195<=$G$4),$G194*C195*$D$6/360,IF(B195<>"",$G194*C195*$G$5/360,IF(AND(B194<>"",B194=$D$5),SUM($E$10:E194),""))) | F195: =IF(D195<>"",D195+E195,"") | G195: =IF($B195<>"",G194-D195,"")
A196: =IF(B195<$D$5,DATE(YEAR(A195),MONTH(A195)+1,DAY(A195)),IF(B195=$D$5,"Tổng","")) | B196: =IF(B195<$D$5,B195+1,"") | C196: =IF(B196<>"",A196-A195,"") | D196: =IF($B195<$D$5,$D$4/$D$5,IF($B195=$D$5,$D$4,"")) | E196: =IF(AND($B196<>"",$B196<=$G$4),$G195*C196*$D$6/360,IF(B196<>"",$G195*C196*$G$5/360,IF(AND(B195<>"",B195=$D$5),SUM($E$10:E195),""))) | F196: =IF(D196<>"",D196+E196,"") | G196: =IF($B196<>"",G195-D196,"")
A197: =IF(B196<$D$5,DATE(YEAR(A196),MONTH(A196)+1,DAY(A196)),IF(B196=$D$5,"Tổng","")) | B197: =IF(B196<$D$5,B196+1,"") | C197: =IF(B197<>"",A197-A196,"") | D197: =IF($B196<$D$5,$D$4/$D$5,IF($B196=$D$5,$D$4,"")) | E197: =IF(AND($B197<>"",$B197<=$G$4),$G196*C197*$D$6/360,IF(B197<>"",$G196*C197*$G$5/360,IF(AND(B196<>"",B196=$D$5),SUM($E$10:E196),""))) | F197: =IF(D197<>"",D197+E197,"") | G197: =IF($B197<>"",G196-D197,"")
A198: =IF(B197<$D$5,DATE(YEAR(A197),MONTH(A197)+1,DAY(A197)),IF(B197=$D$5,"Tổng","")) | B198: =IF(B197<$D$5,B197+1,"") | C198: =IF(B198<>"",A198-A197,"") | D198: =IF($B197<$D$5,$D$4/$D$5,IF($B197=$D$5,$D$4,"")) | E198: =IF(AND($B198<>"",$B198<=$G$4),$G197*C198*$D$6/360,IF(B198<>"",$G197*C198*$G$5/360,IF(AND(B197<>"",B197=$D$5),SUM($E$10:E197),""))) | F198: =IF(D198<>"",D198+E198,"") | G198: =IF($B198<>"",G197-D198,"")
A199: =IF(B198<$D$5,DATE(YEAR(A198),MONTH(A198)+1,DAY(A198)),IF(B198=$D$5,"Tổng","")) | B199: =IF(B198<$D$5,B198+1,"") | C199: =IF(B199<>"",A199-A198,"") | D199: =IF($B198<$D$5,$D$4/$D$5,IF($B198=$D$5,$D$4,"")) | E199: =IF(AND($B199<>"",$B199<=$G$4),$G198*C199*$D$6/360,IF(B199<>"",$G198*C199*$G$5/360,IF(AND(B198<>"",B198=$D$5),SUM($E$10:E198),""))) | F199: =IF(D199<>"",D199+E199,"") | G199: =IF($B199<>"",G198-D199,"")
A200: =IF(B199<$D$5,DATE(YEAR(A199),MONTH(A199)+1,DAY(A199)),IF(B199=$D$5,"Tổng","")) | B200: =IF(B199<$D$5,B199+1,"") | C200: =IF(B200<>"",A200-A199,"") | D200: =IF($B199<$D$5,$D$4/$D$5,IF($B199=$D$5,$D$4,"")) | E200: =IF(AND($B200<>"",$B200<=$G$4),$G199*C200*$D$6/360,IF(B200<>"",$G199*C200*$G$5/360,IF(AND(B199<>"",B199=$D$5),SUM($E$10:E199),""))) | F200: =IF(D200<>"",D200+E200,"") | G200: =IF($B200<>"",G199-D200,"")
A201: =IF(B200<$D$5,DATE(YEAR(A200),MONTH(A200)+1,DAY(A200)),IF(B200=$D$5,"Tổng","")) | B201: =IF(B200<$D$5,B200+1,"") | C201: =IF(B201<>"",A201-A200,"") | D201: =IF($B200<$D$5,$D$4/$D$5,IF($B200=$D$5,$D$4,"")) | E201: =IF(AND($B201<>"",$B201<=$G$4),$G200*C201*$D$6/360,IF(B201<>"",$G200*C201*$G$5/360,IF(AND(B200<>"",B200=$D$5),SUM($E$10:E200),""))) | F201: =IF(D201<>"",D201+E201,"") | G201: =IF($B201<>"",G200-D201,"")
A202: =IF(B201<$D$5,DATE(YEAR(A201),MONTH(A201)+1,DAY(A201)),IF(B201=$D$5,"Tổng","")) | B202: =IF(B201<$D$5,B201+1,"") | C202: =IF(B202<>"",A202-A201,"") | D202: =IF($B201<$D$5,$D$4/$D$5,IF($B201=$D$5,$D$4,"")) | E202: =IF(AND($B202<>"",$B202<=$G$4),$G201*C202*$D$6/360,IF(B202<>"",$G201*C202*$G$5/360,IF(AND(B201<>"",B201=$D$5),SUM($E$10:E201),""))) | F202: =IF(D202<>"",D202+E202,"") | G202: =IF($B202<>"",G201-D202,"")
A203: =IF(B202<$D$5,DATE(YEAR(A202),MONTH(A202)+1,DAY(A202)),IF(B202=$D$5,"Tổng","")) | B203: =IF(B202<$D$5,B202+1,"") | C203: =IF(B203<>"",A203-A202,"") | D203: =IF($B202<$D$5,$D$4/$D$5,IF($B202=$D$5,$D$4,"")) | E203: =IF(AND($B203<>"",$B203<=$G$4),$G202*C203*$D$6/360,IF(B203<>"",$G202*C203*$G$5/360,IF(AND(B202<>"",B202=$D$5),SUM($E$10:E202),""))) | F203: =IF(D203<>"",D203+E203,"") | G203: =IF($B203<>"",G202-D203,"")
A204: =IF(B203<$D$5,DATE(YEAR(A203),MONTH(A203)+1,DAY(A203)),IF(B203=$D$5,"Tổng","")) | B204: =IF(B203<$D$5,B203+1,"") | C204: =IF(B204<>"",A204-A203,"") | D204: =IF($B203<$D$5,$D$4/$D$5,IF($B203=$D$5,$D$4,"")) | E204: =IF(AND($B204<>"",$B204<=$G$4),$G203*C204*$D$6/360,IF(B204<>"",$G203*C204*$G$5/360,IF(AND(B203<>"",B203=$D$5),SUM($E$10:E203),""))) | F204: =IF(D204<>"",D204+E204,"") | G204: =IF($B204<>"",G203-D204,"")
A205: =IF(B204<$D$5,DATE(YEAR(A204),MONTH(A204)+1,DAY(A204)),IF(B204=$D$5,"Tổng","")) | B205: =IF(B204<$D$5,B204+1,"") | C205: =IF(B205<>"",A205-A204,"") | D205: =IF($B204<$D$5,$D$4/$D$5,IF($B204=$D$5,$D$4,"")) | E205: =IF(AND($B205<>"",$B205<=$G$4),$G204*C205*$D$6/360,IF(B205<>"",$G204*C205*$G$5/360,IF(AND(B204<>"",B204=$D$5),SUM($E$10:E204),""))) | F205: =IF(D205<>"",D205+E205,"") | G205: =IF($B205<>"",G204-D205,"")
A206: =IF(B205<$D$5,DATE(YEAR(A205),MONTH(A205)+1,DAY(A205)),IF(B205=$D$5,"Tổng","")) | B206: =IF(B205<$D$5,B205+1,"") | C206: =IF(B206<>"",A206-A205,"") | D206: =IF($B205<$D$5,$D$4/$D$5,IF($B205=$D$5,$D$4,"")) | E206: =IF(AND($B206<>"",$B206<=$G$4),$G205*C206*$D$6/360,IF(B206<>"",$G205*C206*$G$5/360,IF(AND(B205<>"",B205=$D$5),SUM($E$10:E205),""))) | F206: =IF(D206<>"",D206+E206,"") | G206: =IF($B206<>"",G205-D206,"")
A207: =IF(B206<$D$5,DATE(YEAR(A206),MONTH(A206)+1,DAY(A206)),IF(B206=$D$5,"Tổng","")) | B207: =IF(B206<$D$5,B206+1,"") | C207: =IF(B207<>"",A207-A206,"") | D207: =IF($B206<$D$5,$D$4/$D$5,IF($B206=$D$5,$D$4,"")) | E207: =IF(AND($B207<>"",$B207<=$G$4),$G206*C207*$D$6/360,IF(B207<>"",$G206*C207*$G$5/360,IF(AND(B206<>"",B206=$D$5),SUM($E$10:E206),""))) | F207: =IF(D207<>"",D207+E207,"") | G207: =IF($B207<>"",G206-D207,"")
... A251: =IF(B250<$D$5,DATE(YEAR(A250),MONTH(A250)+1,DAY(A250)),IF(B250=$D$5,"Tổng","")) | B251: =IF(B250<$D$5,B250+1,"") | C251: =IF(B251<>"",A251-A250,"") | D251: =IF($B250<$D$5,$D$4/$D$5,IF($B250=$D$5,$D$4,"")) | E251: =IF(AND($B251<>"",$B251<=$G$4),$G250*C251*$D$6/360,IF(B251<>"",$G250*C251*$G$5/360,IF(AND(B250<>"",B250=$D$5),SUM($E$10:E250),""))) | F251: =IF(D251<>"",D251+E251,"") | G251: =IF($B251<>"",G250-D251,"")
...

Sheet Price Quote
E1: =NOW() -> 45958.743 | F1: Khung thuế HCM | G1: =P10 -> 0 | H1: CHI PHÍ ĐĂNG KÝ | J1: GỐC | K1: KHÔNG XE | L1: CP ỨNG | M1: LƯU Ý THUẾ
D2: Discount gift code: | E2: =RAND()*99999999 -> 37516085 | F2: Lệch | G2: =D14-G1 -> 0 | H2: TP.HCM | I2: 4000000 | J2: 2400000 | K2: Không xe | L2: 1500000
G3: ss | H3: Tây Ninh | I3: 5000000 | J3: 3500000 | K3: Xe | L3: 1500000
A4: Estimation of Car License Fee (Grand new car) | G4: ss | H4: Bình Dương | I4: 4000000 | J4: 2800000 | K4: Không xe | L4: 1000000
F5: =P7 -> 299000000 | H5: Đồng Nai | I5: 4000000 | J5: 2800000 | K5: Không xe | L5: 1500000 | P5: 0
A6: - The quotation is valid for 48 hours from the issuance time. - The estimated costs will be refunded if there is a surplus after the invoice is generated. - Gift vouchers and promotions are subject to availability at the time of vehicle pickup. - The validity period of gift vouchers is 48 hours from the activation time. - Note: Bank payment is estimated based on the current highest interest rate. Customers who are eligible for better loan rates will have better options. | F6: VIP | H6: Vũng Tàu | I6: 5500000 | J6: 3500000 | K6: 6000000 | L6: 1500000
A7: To: | B7: =F6 -> VIP | F7: Dòng xe | G7: VF.3 | H7: Long An | I7: 5000000 | J7: 3500000 | K7: 6000000 | L7: 1500000 | M7: Đăng Ký Xe Định Quán + 1tr5 | N7: 3000000 | P7: =VLOOKUP(G8,Data!B2:C29,2,0) -> 299000000
A8: Car Model : | B8: =G8 -> Vinfast VF3 | F8: Loại xe : | G8: Vinfast VF3 | H8: Ninh Thuận | I8: 7300000 | J8: 5500000 | K8: Xe | N8: 3500000 | P8: =VLOOKUP(G8,Data!F2:G29,2,0) -> 0
A9: Price : | D9: =P7 -> 299000000 | E9: VND | F9: Trả trước : | G9: 0.2 | H9: Bình Thuận | I9: 6200000 | J9: 4500000 | K9: 7000000 | N9: 4000000 | O9: 531000 | P9: =VLOOKUP(G8,Data!N2:O29,2,0) -> 299000000 | Q9: =VLOOKUP(G8,Data!AM2:AN29,2,0) -> 287040000
A10: Discount : | D10: =G19 -> 11960000 | E10: VND | F10: Tổng tiền đưa trước | G10: =D31 -> 86714440 | H10: Bình Phước | I10: 6500000 | J10: 4500000 | K10: 6000000 | L10: 3300000 | N10: 5000000 | O10: 847000 | P10: =VLOOKUP(G8,Data!AE2:AF29,2,0) -> 0
A11: Last Price : | D11: =D9-D10 -> 287040000 | E11: VND | F11: Gia đình : | G11: 531000 | H11: Phan Thiết | I11: 6000000 | J11: 4500000 | N11: 6000000 | O11: 944000 | P11: =P7-P9 -> 0 | Q11: =P7-Q9 -> 11960000
F12: Kinh doanh : | G12: 847000 | H12: Phan Rang | I12: 6500000 | O12: 1205000 | P12: =VLOOKUP(G8,Data!AP2:AQ29,2,0) -> Miễn phí sạc 02 năm tại VGreen
A13: STT | B13: Estimation of Car License Fee | D13: AMOUNT | E13: DISCOUNT | F13: Kinh doanh Taxi : | G13: 1429000 | H13: Nha Trang | I13: 9000000 | J13: 7000000 | K13: Xe | L13: 5000000 | O13: 1429000 | P13: =VLOOKUP(G8,Data!AR2:AS29,2,0) -> Miễn phí bãi đổ xe và ưu tiên hệ sinh thái VINGROUP
A14: 1 | B14: Registration duty (10% of price) | D14: =P8-E14 -> 0 | F14: Gia đình7C: | G14: 943000 | H14: Bình Định | I14: 9500000 | J14: 8000000 | K14: 10000000 | L14: 7500000 | N14: 10000000 | O14: 3240000 | P14: =VLOOKUP(G8,Data!AT2:AU29,2,0) -> 0
A15: 2 | B15: Registration fee (number car) | D15: 20000000 | F15: Kinh Doanh 7C : | G15: 1205000 | H15: Phú Yên | I15: 9200000 | J15: 8000000 | K15: 10000000 | L15: 7000000 | N15: 15000000 | P15: =VLOOKUP(G8,Data!AV2:AW29,2,0) -> 0
A16: 3 | B16: Car certification fee | D16: 45000 | F16: Thuế HN tăng thêm : | G16: =O55-D14 -> 35880000 | H16: Đắk Lắk | I16: 8000000 | J16: 6000000 | L16: 5000000 | N16: 20000000 | P16: =VLOOKUP(G8,Data!AX2:AY29,2,0) -> 0 | Q16: =VLOOKUP(G8,Data!AX2:AY29,2,0) -> 0
A17: 4 | B17: Compulsory assurance 1 year | D17: 2160000 | F17: =IF($P18="*","Tự bù Camera", "Công ty Tặng Camera") -> Công ty Tặng Camera | H17: Đắk Nông | I17: 8000000 | J17: 6500000 | L17: 5000000 | N17: 25000000 | O17: 20000000 | P17: =VLOOKUP(G8,Data!#REF!,2,0) -> #REF!
A18: 5 | B18: Car assurance - optinal 1 year (not contraisn) | D18: 944000 | F18: Giá gốc : | G18: =P7 -> 299000000 | H18: Gia Lai | I18: 8300000 | J18: 5500000 | K18: Không xe | L18: 5000000 | N18: 30000000 | O18: 1000000 | P18: =VLOOKUP(G8,Data!AZ2:BA29,2,0) -> 0
A19: 6 | B19: Fee to protect street in VN 1 year | C19: 0.011 | D19: =D11*C19 -> 3157440 | F19: Giảm giá : | G19: =IF(G20>G21,G20,G21) -> 11960000 | H19: Kom Tum | I19: 9500000 | J19: 9000000 | K19: Xe | L19: 5000000 | N19: 35000000 | O19: 500000
A20: 7 | B20: Car license number service (in HCMC) | D20: 3000000 | F20: Chương Trình 2022 : | G20: =P11 -> 0 | H20: Đà Lạt | I20: 8300000 | J20: 5000000 | L20: 5000000 | N20: 40000000 | O20: 200000 | P20: Trắng | Q20: - 5L Nguyên liệu
A21: 8 | B21: Car decoration package | D21: =G22 -> 0 | F21: Chương Trình 2023 : | G21: =Q11 -> 11960000 | N21: 45000000 | Q21: - Bộ lên kiếng tự động
A22: Total registration fee | D22: =SUM(D14:D21) -> 29306440 | F22: Gói Trang Trí | H22: Đà Nẵng | I22: 10000000 | J22: 9000000 | K22: Không xe | L22: 5000000 | N22: 50000000 | O22: 0 | P22: Bạc | Q22: - Dán phim cách nhiệt Bh 10 Năm
A23: CASH | H23: Huế | I23: 10000000 | K23: Không xe | L23: 5000000 | N23: 60000000 | O23: 0.01 | P23: Đỏ | Q23: - Lót sàn cách âm , chống cháy
B24: Base Price : | D24: =D11 -> 287040000 | H24: Thanh Hóa | I24: 11000000 | J24: 10000000 | K24: Không xe | L24: 5000000 | O24: 0.011 | P24: Đen | Q24: - Lót sàn 5D
B25: Estimation of Car License Fee : | D25: =D22 -> 29306440 | H25: Nghệ An | I25: 11000000 | J25: 9000000 | K25: Không xe | L25: 5000000 | O25: 0.012 | P25: Vàng cát | Q25: - Camera hành trình
B26: Completed : | D26: =D24+D25 -> 316346440 | E26: VND | H26: Tiền Giang | I26: 5000000 | J26: 3500000 | K26: 6000000 | L26: 5000000 | O26: 0.013 | P26: Vàng be | Q26: - Thẻ nhớ hành trình
A27: INSTALLMENT | H27: Bến Tre | I27: 6000000 | J27: 4000000 | K27: Xe | L27: 5000000 | O27: 0.014 | P27: Xanh | Q27: - Tẩu sạc USB
B28: Banking Loan : | C28: =100%-C29 -> 0.8 | D28: =C28*D11-E28 -> 229632000 | F28: Ngân hàng cho vay : | G28: 600000000 | H28: Trà Vinh | I28: 6200000 | J28: 4500000 | K28: 7000000 | L28: 5000000 | O28: 0.015 | P28: Cam | Q28: - Phủ gầm
B29: Deposit | C29: =G9 -> 0.2 | D29: =F5-D28+G19-D10-G19 -> 57408000 | E29: (1) | F29: Chênh lệch | G29: =D28-G28 -> -370368000 | H29: An Giang | I29: 6200000 | J29: 5000000 | K29: 7000000 | L29: 6000000 | O29: 0.016 | P29: Xanh chuối | Q29: - Phủ Ceramic
B30: Estimation of Car License Fee : | D30: =D22 -> 29306440 | E30: (2) | H30: Kiên Giang | I30: 6200000 | J30: 5500000 | K30: 7000000 | L30: 5000000 | O30: 0.017 | Q30: - Viền che mưa
B31: Total (1) + (2) : | D31: =(D11-F5)+D30+D29-G19+D10+G19 -> 86714440 | E31: VND | F31: Tips : Xác định nhu cầu khách hàng | H31: Hậu Giang | I31: 6200000 | J31: 5300000 | K31: 7000000 | L31: 5000000 | O31: 0.018 | Q31: - Bệ bước chân cao cấp
F32: 1. Anh/ chị có dự định nhận xe trong tháng không hay mình tham khảo trước để em tư vấn anh/ chị luôn ạ ! | H32: Cần Thơ | I32: 6200000 | J32: 4500000 | K32: 7000000 | L32: 5000000 | O32: 0.019 | Q32: - Hộp đen kinh doanh
A33: Free gift accessory | B33: - Car cover, floor mat, leather-wrapped steering wheel, fire extinguisher, specialized towel | C33: INSTALLMENT | E33: Amount per month | H33: Đồng Tháp | I33: 6000000 | J33: 4500000 | K33: 8000000 | L33: 1500000 | O33: 0.02 | Q33: - Gói bảo hành nâng cấp 05 năm
